Workbook

Sheet DIODE
A2: DIODE STORE STOCK
A4: RAWMATERIAL CODE | B4: CATAGARE NO | C4: SLNO | D4: PART NO | E4: DESCRIPTION | F4: PHY QTY | G4: RECEIPT | H4: ISSUE | I4: BALANCE | J4: UNIT PRICE | K4: AMOUNT
A5: VN0089DE05001 | B5: DE05001 | C5: 1 | D5: MB10S ( MD7S) | E5: BRIDGE DIODE | F5: 0 | G5: 0 | H5: 0 | I5: 3000 | J5: 4.5 | K5: =I5*J5 -> 13500
A6: SM0105DE05002 | B6: DE05002 | C6: 2 | D6: SMUA2121 207 1P | E6: BRIDGE DIODE | I6: =F6+G6-H6 -> 0 | J6: 3.5 | K6: =I6*J6 -> 0
A7: SM0105DE05003 | B7: DE05003 | C7: 3 | D7: MSU2N60 | E7: BRIDGE DIODE | I7: =F7+G7-H7 -> 0 | J7: 5.52 | K7: =I7*J7 -> 0
A8: VN0064DE05004 | B8: DE05004 | C8: 4 | D8: SIM BRIDGE DIODE | E8: BRIDGE DIODE | I8: =F8+G8-H8 -> 0 | J8: 5.9 | K8: =I8*J8 -> 0
A9: SM0105DE05005 | B9: DE05005 | C9: 5 | D9: S2G | E9: BRIDGE DIODE | I9: =F9+G9-H9 -> 0 | J9: 0 | K9: =I9*J9 -> 0
A10: VN0089DE05006 | B10: DE05006 | C10: 6 | D10: SM4007 MELF | E10: BRIDGE DIODE | F10: 250 | I10: =F10+G10-H10 -> 250 | J10: 0.65 | K10: =I10*J10 -> 162.5
A11: VN0101DE05007 | B11: DE05007 | C11: 7 | D11: SR3100 | E11: DIODE | F11: 137 | I11: =F11+G11-H11 -> 137 | J11: 2.9 | K11: =I11*J11 -> 397.3
A12: VN0101DE05008 | B12: DE05008 | C12: 8 | D12: IN4007 | E12: DIODE | F12: 820 | G12: 60000 | H12: =10+10 -> 20 | I12: =F12+G12-H12 -> 60800 | J12: 1 | K12: =I12*J12 -> 60800
A13: VN0064DE05009 | B13: DE05009 | C13: 9 | D13: PK IN 5333B | E13: DIODE | I13: =F13+G13-H13 -> 0 | J13: 2.9 | K13: =I13*J13 -> 0
A14: VN0064DE05010 | B14: DE05010 | C14: 10 | D14: SR260 | E14: DIODE | I14: =F14+G14-H14 -> 0 | J14: 2.9 | K14: =I14*J14 -> 0
A15: VN0064DE05011 | B15: DE05011 | C15: 11 | D15: ES2G /MURS360 | E15: DIODE | G15: =400+750+1500 -> 2650 | H15: =400+200+550 -> 1150 | I15: =F15+G15-H15 -> 1500 | J15: 3.5 | K15: =I15*J15 -> 5250
A16: VN0101DE05012 | B16: DE05012 | C16: 12 | D16: SMD DIODE 39V/S0D-80 | E16: ZENER DIODE | F16: 30 | I16: =F16+G16-H16 -> 30 | J16: 1.47 | K16: =I16*J16 -> 44.1
A17: VN0082DE05013 | B17: DE05013 | C17: 13 | D17: MUR460 | E17: DIODE | F17: =603+4+250+3000+95+603 -> 4555 | G17: 4800 | H17: =10+702+1000+5 -> 1717 | I17: 11138 | J17: 3.5 | K17: =I17*J17 -> 38983
A18: VN0082DE05014 | B18: DE05014 | C18: 14 | D18: 10K TRIM POT | E18: TRIM POT | G18: 5000 | I18: =F18+G18-H18 -> 5000 | J18: 1.65 | K18: =I18*J18 -> 8250
A19: VN0089DE05015 | B19: DE05015 | C19: 15 | D19: SMD DIODE 1N4148 SOD-123 | E19: DIODE | G19: 2000 | H19: 2000 | I19: =F19+G19-H19 -> 0 | J19: 1.1 | K19: =I19*J19 -> 0
A20: VN0089DE05016 | B20: DE05016 | C20: 16 | D20: US1K | E20: DIODE | I20: =F20+G20-H20 -> 0 | J20: 4.9 | K20: =I20*J20 -> 0
A21: VN0009DE05017 | B21: DE05017 | C21: 17 | D21: MUR260/HER206 | E21: DIODE | F21: 500 | I21: =F21+G21-H21 -> 500 | J21: 3 | K21: =I21*J21 -> 1500
B22: DE05018 | C22: 18 | D22: 1N5819 | E22: DIODE | I22: =F22+G22-H22 -> 0 | K22: =I22*J22 -> 0
B23: DE05019 | D23: SMD DIODE USIM | E23: DIODE | I23: =F23+G23-H23 -> 0 | K23: =I23*J23 -> 0
B24: DE05020 | D24: SMD DIODE 1N4007 (m7) | E24: SMD DIODE | G24: =10000+10000 -> 20000 | I24: =F24+G24-H24 -> 20000 | J24: 0.45 | K24: =I24*J24 -> 9000
B25: DE05021 | D25: SMD DIODE UF4003 | E25: SMD DIODE | I25: =F25+G25-H25 -> 0 | K25: =I25*J25 -> 0
B26: DE05022 | D26: DIODE UF 4007 | E26: DIODE | F26: 0 | G26: 30000 | I26: =F26+G26-H26 -> 30000 | J26: 0.65 | K26: =I26*J26 -> 19500
I27: =F27+G27-H27 -> 0 | J27: TOTAL | K27: =SUM(K5:K26) -> 157386.9

Sheet LEDS
A3: LED"S STORE STOCK
A5: RAWMATERIAL CODE | B5: CATAGARE NO | C5: SLNO | D5: PART NO | E5: DESCRIPTION | F5: PHY QTY | G5: RECEIPT | H5: ISSUE | I5: BALANCE | J5: UNIT PRICE | K5: AMOUNT
A6: SMLW56LD00001 | B6: LD00001 | C6: 1 | D6: SMLW56RGB,1W | E6: LED | F6: 956 | I6: =F6+G6-H6 -> 956 | J6: 30 | K6: =I6*J6 -> 28680
A7: VN0094LD00002 | B7: LD00002 | C7: 2 | D7: EW3528D-0201-XBXC-0558 | E7: LED | F7: 910 | I7: 200 | J7: 1.2 | K7: =I7*J7 -> 240
A8: VN0110LD00003 | B8: LD00003 | C8: 3 | D8: WU2180-07 ,3WATT LED | E8: LED | F8: 0 | I8: =F8+G8-H8 -> 0 | J8: 30 | K8: =I8*J8 -> 0
A9: VN0094LD00004 | B9: LD00004 | C9: 4 | D9: FM-5630WLS-460W-R80(WW) | E9: LED | F9: 7449 | I9: 9547 | J9: 6.5 | K9: =I9*J9 -> 62055.5
A10: VN0094LD00005 | B10: LD00005 | C10: 5 | D10: FM-5630WNS-460W-R80 (MW) | E10: LED | F10: 7400 | H10: =1500+1400+5 -> 2905 | I10: 5159 | J10: 6 | K10: =I10*J10 -> 30954
A11: VN0094LD00006 | B11: LD00006 | C11: 6 | D11: FM-3528WNS-460R ( NT10TN1S23B) | E11: LED | F11: 275 | H11: =3+5 -> 8 | I11: 0 | J11: 1.85 | K11: =I11*J11 -> 0
A12: VN0108LD00007 | B12: LD00007 | C12: 7 | D12: PM2B-1LWE | E12: LEDS | F12: 0 | I12: =F12+G12-H12 -> 0 | J12: 1 | K12: =I12*J12 -> 0
A13: VN0109LD00008 | B13: LD00008 | C13: 8 | D13: NICHIA 0.5 WATT MILKY WHITE | E13: LEDS | F13: 0 | I13: =F13+G13-H13 -> 0 | J13: 1.5 | K13: =I13*J13 -> 0
A14: VN0030LD00009 | B14: LD00009 | C14: 9 | D14: 6070 HIGH POWER EDISON LEDS | E14: LEDS | F14: 0 | I14: =F14+G14-H14 -> 0 | J14: 27 | K14: =I14*J14 -> 0
A15: VN0030LD00010 | B15: LD00010 | C15: 10 | D15: 91 LED TUBE LIGHT STRIP (EDISON LED) | E15: LEDS | F15: 0 | I15: =F15+G15-H15 -> 0 | J15: 1000 | K15: =I15*J15 -> 0
A16: VN0107LD00011 | B16: LD00011 | C16: 11 | D16: LEUWD1W401 OSRAM STAR LED | E16: SAMPLES | F16: 0 | I16: =F16+G16-H16 -> 0 | J16: 45 | K16: =I16*J16 -> 0
A17: VN0107LD00012 | B17: LD00012 | C17: 12 | D17: LYG6SP-CBDB-45-1-140-R182 OSRAM LEDS | E17: SAMPLES | F17: 30 | I17: =F17+G17-H17 -> 30 | J17: 45 | K17: =I17*J17 -> 1350
A18: VN0094LD00013 | B18: LD00013 | C18: 13 | D18: LED FM-P3528WNS-460W -R80-150mA (MILKY WHITE) | E18: LED | F18: 1315 | G18: =3000+2980+15000 -> 20980 | H18: =5+3000+2975+9000+5+4+20 -> 15009 | I18: 6669 | J18: 4.35 | K18: =I18*J18 -> 29010.15
A19: VN0094LD00014 | B19: LD00014 | C19: 14 | D19: LED 5630 1CHIP 38LUM@100mA SEOUL | E19: LED | F19: 0 | I19: =F19+G19-H19 -> 0 | J19: 5 | K19: =I19*J19 -> 0
B20: LD00015 | C20: 20 | D20: FM-T3528WLS-460R -R70 | E20: LED | F20: 52 | G20: 3000 | I20: 280 | J20: 1.4 | K20: =I20*J20 -> 392
A21: VN0094LD00016 | B21: LD00016 | C21: 16 | D21: FM-3014WNS-460R | E21: LED | F21: =6000+2800 -> 8800 | I21: 8800 | J21: 1.65 | K21: =I21*J21 -> 14520
A22: VN0094LD00017 | B22: LD00017 | C22: 17 | D22: FM-3014WLS-460R-R70 | E22: LED | F22: 9000 | I22: 9000 | J22: 1.65 | K22: =I22*J22 -> 14850
B23: LD00018 | C23: 18 | D23: FM-P3528WNS-460W(150mA) | E23: LED | F23: 0 | G23: 0 | H23: 0 | I23: 0 | J23: 0 | K23: 0
B24: LD00019 | C24: 19 | D24: FM-T3528WNS-460R LEDS | E24: LED | F24: 0 | G24: 0 | H24: 0 | I24: 0 | J24: 0 | K24: 0
B25: LD00020 | C25: 20 | D25: YXG-3528EF1ZWF2 | E25: LED | F25: 2000 | H25: 104 | I25: 1800 | J25: 1.85 | K25: =I25*J25 -> 3330
B26: LD00021 | C26: 21 | D26: FM-P3528WNS-460Q(60mA) | E26: LED | F26: 745 | G26: 15000 | H26: 12043 | I26: 498805 | J26: 1.61 | K26: =J26*I26 -> 803076.05
B27: LD00022 | C27: 22 | D27: NFSW757DT | E27: LED | F27: 2000 | G27: 110 | H27: 0 | I27: 2000 | J27: 0 | K27: 0
A28: VN0094LD00015 | B28: LD00023 | C28: 23 | D28: FM-T3528WNS-460R LEDS | E28: LED | F28: 85 | H28: =10+75 -> 85 | I28: 3400 | J28: 1.85 | K28: =I28*J28 -> 6290
B29: LD00024 | C29: 24 | D29: LED FM-P3528WLS-460W -R80-150mA (WARM WHITE) | E29: LED | I29: 1200 | J29: 2.6 | K29: =I29*J29 -> 3120
J30: TOTAL | K30: =SUM(K6:K29) -> 997867.7

Sheet PCB
A2: MC PCB STORE STOCK
A4: RAWMATERIAL CODE | B4: CATAGARE NO | C4: SLNO | D4: PART NO | E4: DESCRIPTION | F4: PHY QTY | G4: RECEIPT | H4: ISSUE | I4: BALANCE | J4: UNIT PRICE | K4: AMOUNT
A5: VN0098PCB09001 | B5: PCB09001 | C5: 1 | D5: TUBE LIGHT 4.4 VER | E5: PCB | I5: =F5+G5-H5 -> 0 | J5: 9 | K5: =I5*J5 -> 0
A6: VN0098PCB09002 | B6: PCB09002 | C6: 2 | D6: E27-SEM REV 3.2 | E6: PCB | I6: =F6+G6-H6 -> 0 | J6: 6.5 | K6: =I6*J6 -> 0
A7: VN0098PCB09003 | B7: PCB09003 | C7: 3 | D7: T10-TUBE LIGHT MCPCB | E7: MC PCB | I7: =F7+G7-H7 -> 0 | J7: 15 | K7: =I7*J7 -> 0
A8: VN0098PCB09004 | B8: PCB09004 | C8: 4 | D8: T10-TUBE LIGHT MCPCB V1 | E8: MC PCB | I8: =F8+G8-H8 -> 0 | J8: 15 | K8: =I8*J8 -> 0
A9: VN0098PCB09005 | B9: PCB09005 | C9: 5 | D9: T8 TUBE LIGHT MC PCB 140 LEDS | E9: MC PCB | I9: 8000 | J9: 6 | K9: =I9*J9 -> 48000
A10: VN0098PCB09006 | B10: PCB09006 | C10: 6 | D10: T8 TUBE LIGHT MC PCB 150 LEDS | E10: MC PCB | I10: =F10+G10-H10 -> 0 | J10: 6 | K10: =I10*J10 -> 0
A11: VN0098PCB09007 | B11: PCB09007 | C11: 7 | D11: 91 LEDS -Tubelight MCPCB | E11: MC PCB | I11: =F11+G11-H11 -> 0 | J11: 410 | K11: =I11*J11 -> 0
A12: VN0098PCB09008 | B12: PCB09008 | C12: 8 | D12: T8 TUBE LIGHT MC PCB | E12: MC PCB | I12: =F12+G12-H12 -> 0 | J12: 6 | K12: =I12*J12 -> 0
A13: VN0098PCB09009 | B13: PCB09009 | C13: 9 | D13: T8 TUBE LIGHT MC PCB V1 | E13: MC PCB | I13: =F13+G13-H13 -> 0 | J13: 6 | K13: =I13*J13 -> 0
A14: VN0098PCB09010 | B14: PCB09010 | C14: 10 | D14: SEM VER 1.0 MC PCB 140LEDS | E14: MC PCB | I14: 6958 | J14: 400 | K14: =I14*J14 -> 2783200
A15: VN0098PCB09011 | B15: PCB09011 | C15: 11 | D15: SEM VER 1.0 MC PCB 120LEDS | E15: MC PCB | I15: =F15+G15-H15 -> 0 | J15: 360 | K15: =I15*J15 -> 0
A16: VN0111PCB09012 | B16: PCB09012 | C16: 12 | D16: CIRCULAR MC PCB 15LED | E16: MC PCB | I16: =F16+G16-H16 -> 0 | J16: 20 | K16: =I16*J16 -> 0
A17: VN0111PCB09013 | B17: PCB09013 | C17: 13 | D17: CIRCULAR MC PCB 10LED | E17: MC PCB | I17: =F17+G17-H17 -> 0 | J17: 20 | K17: =I17*J17 -> 0
A18: VN0111PCB09014 | B18: PCB09014 | C18: 14 | D18: 10 WATT CIRCULAR MC PCB WITH LED ASSEMBLED | E18: MC PCB | F18: =76+39 -> 115 | H18: =1+1 -> 2 | I18: =F18+G18-H18 -> 113 | J18: 230 | K18: =I18*J18 -> 25990
A19: VN0111PCB09015 | B19: PCB09015 | C19: 15 | D19: 15 WATT CIRCULAR MC PCB WITH LED ASSEMBLED | E19: MC PCB | F19: 24 | I19: =F19+G19-H19 -> 24 | J19: 340 | K19: =I19*J19 -> 8160
A20: VN0111PCB09016 | B20: PCB09016 | C20: 16 | D20: 20 WATT CIRCULAR MC PCB WITH LED ASSEMBLED | E20: MC PCB | F20: 5 | I20: =F20+G20-H20 -> 5 | J20: 410 | K20: =I20*J20 -> 2050
A21: VN0111PCB09017 | B21: PCB09017 | C21: 17 | D21: 3 WATT CIRCULAR MC PCB WITH LED ASSEMBLED(CN) | E21: MC PCB | F21: 475 | H21: =30+6 -> 36 | I21: =F21+G21-H21 -> 439 | J21: 10 | K21: =I21*J21 -> 4390
A22: VN0111PCB09018 | B22: PCB09018 | C22: 18 | D22: 5 WATT CIRCULAR MC PCB WITH LED ASSEMBLED(CN) | E22: MC PCB | F22: 166 | H22: =30+3+2+1+1+1+1 -> 39 | I22: =F22+G22-H22 -> 127 | J22: 10 | K22: =I22*J22 -> 1270
A23: VN0111PCB09019 | B23: PCB09019 | C23: 19 | D23: 9 WATT CIRCULAR MC PCB WITH LED ASSEMBLED(CN) | E23: MC PCB | I23: =F23+G23-H23 -> 0 | J23: 10 | K23: =I23*J23 -> 0
A24: VN0111PCB09020 | B24: PCB09020 | C24: 20 | D24: 15 WATT CIRCULAR MC PCB WITH LED ASSEMBLED(CN) | E24: MC PCB | I24: =F24+G24-H24 -> 0 | J24: 165 | K24: =I24*J24 -> 0
A25: VN0111PCB09021 | B25: PCB09021 | C25: 21 | D25: 3 WATT CIRCULAR MC PCB(CHINAN) | E25: MC PCB | I25: =F25+G25-H25 -> 0 | J25: 3 | K25: =I25*J25 -> 0
A26: VN0111PCB09022 | B26: PCB09022 | C26: 22 | D26: 6 WATT CIRCULAR MC PCB(CN) | E26: MC PCB | F26: 35 | I26: =F26+G26-H26 -> 35 | J26: 5 | K26: =I26*J26 -> 175
A27: VN0111PCB09023 | B27: PCB09023 | C27: 23 | D27: 18 WATT CIRCULAR MC PCB(CN) | E27: MC PCB | I27: =F27+G27-H27 -> 0 | J27: 7 | K27: =I27*J27 -> 0
A28: VN0111PCB09024 | B28: PCB09024 | C28: 24 | D28: 30 WATT CIRCULAR MC PCB (CN) | E28: MC PCB | I28: =F28+G28-H28 -> 0 | J28: 10 | K28: =I28*J28 -> 0
A29: VN0098PCB09025 | B29: PCB09025 | C29: 25 | D29: 20 Watt circular | E29: MCPCB | I29: =F29+G29-H29 -> 0 | J29: 10 | K29: =I29*J29 -> 0
A30: VN0098PCB09026 | B30: PCB09026 | C30: 26 | D30: 10 WATT CIRCULAR | E30: MCPCB | I30: =F30+G30-H30 -> 0 | J30: 10 | K30: =I30*J30 -> 0
A31: VN0098PCB09027 | B31: PCB09027 | C31: 27 | D31: 15 WATT CIRCULAR | E31: MCPCB | F31: 14 | I31: =F31+G31-H31 -> 14 | J31: 12 | K31: =I31*J31 -> 168
A32: VN0098PCB09028 | B32: PCB09028 | C32: 28 | D32: SM 18 WATT VER 4.2 | E32: BARE PCB | F32: 2160 | I32: =F32+G32-H32 -> 2160 | J32: 5 | K32: =I32*J32 -> 10800
A33: VN0070PCB09029 | B33: PCB09029 | C33: 29 | D33: SL-CONT | E33: BARE PCB | I33: =F33+G33-H33 -> 0 | J33: 5 | K33: =I33*J33 -> 0
A34: VN0070PCB09030 | B34: PCB09030 | C34: 30 | D34: E27-CS-EM1 | E34: BARE PCB | I34: =F34+G34-H34 -> 0 | J34: 6 | K34: =I34*J34 -> 0
A35: VN0098PCB09031 | B35: PCB09031 | C35: 31 | D35: T8 TUBE LIGHT MC PCB 1 FT | E35: BARE PCB | I35: =F35+G35-H35 -> 0 | J35: 6 | K35: =I35*J35 -> 0
A36: VN0111PCB09032 | B36: PCB09032 | C36: 32 | D36: 3 WATT CIRCULAR MC PCB WITH LED ASSEMBLED(CN)WW | E36: MC PCB | I36: =F36+G36-H36 -> 0 | J36: 22 | K36: =I36*J36 -> 0
A37: VN0111PCB09033 | B37: PCB09033 | C37: 33 | D37: 9 WATT CIRCULAR MC PCB WITH LED ASSEMBLED(CN)WW | E37: MC PCB | I37: =F37+G37-H37 -> 0 | J37: 28 | K37: =I37*J37 -> 0
A38: VN0111PCB09034 | B38: PCB09034 | C38: 34 | D38: 20 WATT CIRCULAR MC PCB WITH LED ASSEMBLEDWW | E38: MC PCB | I38: =F38+G38-H38 -> 0 | J38: 410 | K38: =I38*J38 -> 0
A39: VN0098PCB09035 | B39: PCB09035 | C39: 35 | D39: SM 3300 VER TL 5.8 D/S | E39: MC PCB | I39: =F39+G39-H39 -> 0 | J39: 25.92 | K39: =I39*J39 -> 0
A40: VN0098PCB09036 | B40: PCB09036 | C40: 36 | D40: SM 18 WATT VER 5.4 | E40: PCB | F40: 0 | G40: =3584+1875 -> 5459 | H40: 0 | I40: =G40-H40 -> 5459 | J40: 17.57 | K40: =I40*J40 -> 95914.63
A41: VN0098PCB09037 | B41: PCB09037 | C41: 37 | D41: SM 4-7 WATT 6300B | E41: PCB | I41: =F41+G41-H41 -> 0 | J41: 7 | K41: =I41*J41 -> 0
A42: VN0007PCB09038 | B42: PCB09038 | C42: 38 | D42: 600 MM LED PCB INTEGRATED | E42: PCB | I42: =F42+G42-H42 -> 0 | J42: 111.21 | K42: =I42*J42 -> 0
...

Sheet RESISTOR
D2: RESISTER STORE STOCK
D4: RAWMATERIAL CODE | E4: CATAGARE NO | F4: SLNO | G4: PART NO | H4: DESCRIPTION | I4: PHYSICAL QTY | J4: RECEIPT | K4: ISSUE | L4: BALANCE | M4: UNIT PRICE | N4: AMOUNT
D5: VN0089RS01001 | E5: RS01001 | F5: 1 | G5: 33K/0603/5% | H5: SMD RESISTOR | I5: 300 | L5: =I5+J5-K5 -> 300 | M5: 0.15 | N5: =L5*M5 -> 45
D6: VN0089RS01002 | E6: RS01002 | F6: 2 | G6: 100PF/0805/ 50V /5% | H6: SMD CAPACITOR | I6: 4688 | K6: =10+702+180+35+25+1000+5 -> 1957 | L6: =I6+J6-K6 -> 2731 | M6: 0.6 | N6: =L6*M6 -> 1638.6
D7: VN0089RS01003 | E7: RS01003 | F7: 3 | G7: 432E/0603/1% | H7: SMD RESISTOR | L7: =I7+J7-K7 -> 0 | M7: 0.1 | N7: =L7*M7 -> 0
D8: VN0089RS01004 | E8: RS01004 | F8: 4 | G8: 200K/0603/1% | H8: SMD RESISTOR | I8: 300 | L8: =I8+J8-K8 -> 300 | M8: 0.1 | N8: =L8*M8 -> 30
D9: VN0089RS01005 | E9: RS01005 | F9: 5 | G9: 10E/0603/1% | H9: SMD RESISTOR | L9: =I9+J9-K9 -> 0 | M9: 0.04 | N9: =L9*M9 -> 0
D10: VN0089RS01006 | E10: RS01006 | F10: 6 | G10: 1UF/0805/10% 25 V OR 50V | H10: SMD CAPACITOR | I10: =1000+400+6000 -> 7400 | J10: =2000+1000+8000 -> 11000 | K10: =20+400+702+702+50+1000+2000+10 -> 4884 | L10: =I10+J10-K10 -> 13516 | M10: 0.35 | N10: =L10*M10 -> 4730.6
D11: VN0089RS01007 | E11: RS01007 | F11: 7 | G11: 100K/0603/1% | H11: SMD RESISTOR | L11: =I11+J11-K11 -> 0 | M11: 0.06 | N11: =L11*M11 -> 0
D12: VN0089RS01008 | E12: RS01008 | F12: 8 | G12: MD7S/SO | H12: SMD RESISTOR | L12: =I12+J12-K12 -> 0 | M12: 5.9 | N12: =L12*M12 -> 0
D13: VN0089RS01009 | E13: RS01009 | F13: 9 | G13: 0E/0805 / 5% | H13: SMD RESISTOR | I13: 7090 | J13: 5000 | K13: =10+702+1000+5 -> 1717 | L13: =I13+J13-K13 -> 10373 | M13: 0.04 | N13: =L13*M13 -> 414.92
D14: VN0089RS01010 | E14: RS01010 | F14: 10 | G14: 1E/1206/1% | H14: SMD RESISTOR | I14: 290 | J14: 1000 | K14: 1000 | L14: =I14+J14-K14 -> 290 | M14: 0.1 | N14: =L14*M14 -> 29
D15: VN0089RS01011 | E15: RS01011 | F15: 11 | G15: 330E/1206/1% | H15: SMD RESISTOR | L15: =I15+J15-K15 -> 0 | M15: 0.05 | N15: =L15*M15 -> 0
D16: VN0089RS01012 | E16: RS01012 | F16: 12 | G16: 1UF/0805/25v | H16: SMD RESISTOR | L16: =I16+J16-K16 -> 0 | M16: 1.1 | N16: =L16*M16 -> 0
D17: VN0089RS01013 | E17: RS01013 | F17: 13 | G17: 9.53K/0805/1% | H17: SMD RESISTOR | I17: 1300 | L17: =I17+J17-K17 -> 1300 | M17: 0.07 | N17: =L17*M17 -> 91
D18: VN0089RS01014 | E18: RS01014 | F18: 14 | G18: 68.1K/0805/1% | H18: SMD RESISTOR | I18: 1000 | L18: =I18+J18-K18 -> 1000 | M18: 0.07 | N18: =L18*M18 -> 70
D19: VN0089RS01015 | E19: RS01015 | F19: 15 | G19: 15K/1206/1% | H19: SMD RESISTOR | I19: 1500 | L19: =I19+J19-K19 -> 1500 | M19: 0.07 | N19: =L19*M19 -> 105
D20: VN0089RS01016 | E20: RS01016 | F20: 16 | G20: SM4007/MELF(1A/1KV) | H20: SMD RESISTOR | L20: =I20+J20-K20 -> 0 | M20: 0.65 | N20: =L20*M20 -> 0
D21: VN0089RS01017 | E21: RS01017 | F21: 17 | G21: 332K/1206/1% | H21: SMD RESISTOR | I21: 1500 | L21: =I21+J21-K21 -> 1500 | M21: 0.04 | N21: =L21*M21 -> 60
D22: VN0089RS01018 | E22: RS01018 | F22: 18 | G22: 7.5K/1206/1% | H22: SMD RESISTOR | I22: 0 | J22: 10000 | L22: =I22+J22-K22 -> 10000 | M22: 0.07 | N22: =L22*M22 -> 700
D23: VN0089RS01019 | E23: RS01019 | F23: 19 | G23: FSM 106-TMELF UF4003 | H23: SMD RESISTOR | L23: =I23+J23-K23 -> 0 | M23: 0.65 | N23: =L23*M23 -> 0
D24: VN0089RS01020 | E24: RS01020 | F24: 20 | G24: 1M/0805 / 1% | H24: SMD RESISTOR | I24: 5000 | L24: =I24+J24-K24 -> 5000 | M24: 1 | N24: =L24*M24 -> 5000
D25: VN0089RS01021 | E25: RS01021 | F25: 21 | G25: 100K/0603 | H25: SMD RESISTOR | L25: =I25+J25-K25 -> 0 | M25: 0.06 | N25: =L25*M25 -> 0
D26: VN0089RS01022 | E26: RS01022 | F26: 22 | G26: 100R/0805/1% | H26: SMD RESISTOR | I26: 280 | L26: =I26+J26-K26 -> 280 | M26: 0.05 | N26: =L26*M26 -> 14
D27: VN0089RS01023 | E27: RS01023 | F27: 23 | G27: 10K/0603/1 % | H27: SMD RESISTOR | L27: =I27+J27-K27 -> 0 | M27: 0.05 | N27: =L27*M27 -> 0
D28: VN0089RS01024 | E28: RS01024 | F28: 24 | G28: 1M/0805/1% | H28: SMD RESISTOR | L28: =I28+J28-K28 -> 0 | M28: 0.06 | N28: =L28*M28 -> 0
D29: VN0089RS01025 | E29: RS01025 | F29: 25 | G29: 100E/0805/1% | H29: SMD RESISTOR | I29: 2600 | L29: =I29+J29-K29 -> 2600 | M29: 0.04 | N29: =L29*M29 -> 104
D30: VN0089RS01026 | E30: RS01026 | F30: 26 | G30: 10K/1206/1% | H30: SMD RESISTOR | I30: 5250 | J30: 5000 | L30: =I30+J30-K30 -> 10250 | M30: 0.06 | N30: =L30*M30 -> 615
D31: VN0089RS01027 | E31: RS01027 | F31: 27 | G31: 49.9K/0603/1% | H31: SMD RESISTOR | I31: 450 | L31: =I31+J31-K31 -> 450 | M31: 0.06 | N31: =L31*M31 -> 27
D32: VN0089RS01028 | E32: RS01028 | F32: 28 | G32: 390E/0603/1% | H32: SMD RESISTOR | L32: =I32+J32-K32 -> 0 | M32: 0.05 | N32: =L32*M32 -> 0
D33: VN0089RS01029 | E33: RS01029 | F33: 29 | G33: 150R/1206/1% | H33: SMD RESISTOR | I33: 50 | L33: =I33+J33-K33 -> 50 | M33: 0.05 | N33: =L33*M33 -> 2.5
D34: VN0089RS01030 | E34: RS01030 | F34: 30 | G34: 430R/0603/1% | H34: SMD RESISTOR | L34: =I34+J34-K34 -> 0 | M34: 0.05 | N34: =L34*M34 -> 0
D35: VN0089RS01031 | E35: RS01031 | F35: 31 | G35: 510K/0603/1% | H35: SMD RESISTOR | L35: =I35+J35-K35 -> 0 | M35: 0.06 | N35: =L35*M35 -> 0
D36: VN0089RS01032 | E36: RS01032 | F36: 32 | G36: 1.5K/0805/1% | H36: SMD RESISTOR | L36: =I36+J36-K36 -> 0 | M36: 0.06 | N36: =L36*M36 -> 0
D37: VN0089RS01033 | E37: RS01033 | F37: 33 | G37: 100K/0805/1% | H37: SMD RESISTOR | I37: 60 | J37: 700 | K37: =702+5 -> 707 | L37: 5000 | M37: 0.05 | N37: =L37*M37 -> 250
D38: VN0089RS01034 | E38: RS01034 | F38: 34 | G38: 330E/ 0603/ 1% | H38: SMD RESISTOR | I38: 1200 | L38: =I38+J38-K38 -> 1200 | M38: 0.05 | N38: =L38*M38 -> 60
D39: VN0089RS01035 | E39: RS01035 | F39: 35 | G39: 200K/0603/1% | H39: SMD RESISTOR | L39: =I39+J39-K39 -> 0 | M39: 0.06 | N39: =L39*M39 -> 0
D40: VN0089RS01036 | E40: RS01036 | F40: 36 | G40: 1.8MEG/0805/1% | H40: SMD RESISTOR | L40: =I40+J40-K40 -> 0 | M40: 0.06 | N40: =L40*M40 -> 0
D41: VN0089RS01037 | E41: RS01037 | F41: 37 | G41: 0R/0603/1% | H41: SMD RESISTOR | L41: =I41+J41-K41 -> 0 | M41: 0.06 | N41: =L41*M41 -> 0
D42: VN0089RS01038 | E42: RS01038 | F42: 38 | G42: 3K/1206/1% | H42: SMD RESISTOR | I42: 95 | L42: =I42+J42-K42 -> 95 | M42: 0.05 | N42: =L42*M42 -> 4.75
...

Sheet CONNECTOR
A3: CONNUCTOR STORE STOCK
A5: RAWMATERIAL CODE | B5: CATAGARE NO | C5: SLNO | D5: PART NO | E5: DESCRIPTION | F5: PHY QTY | G5: RECEIPT | H5: ISSUE | I5: BALANCE | J5: UNIT PRICE | K5: AMOUNT
A6: VN0031CR18001 | B6: CR18001 | C6: 1 | D6: 2 Pin Ac connector | E6: connector | F6: 0 | I6: =F6+G6-H6 -> 0 | J6: 10 | K6: =I6*J6 -> 0
A7: VN0031CR18002 | B7: CR18002 | C7: 2 | D7: 2 Pin CPU + PIN MALE | E7: connuctor | F7: 0 | I7: =F7+G7-H7 -> 0 | J7: 1.5 | K7: =I7*J7 -> 0
A8: VN0031CR18003 | B8: CR18003 | C8: 3 | D8: 2 Pin CPU + PIN FEMALE | E8: connuctor | F8: 0 | I8: =F8+G8-H8 -> 0 | J8: 1.5 | K8: =I8*J8 -> 0
A9: VN0031CR18004 | B9: CR18004 | C9: 4 | D9: 5 Pin Ac connector | E9: connuctor | F9: 0 | I9: =F9+G9-H9 -> 0 | J9: 10 | K9: =I9*J9 -> 0
B10: CR18005 | C10: 5 | D10: 2 PIN PBT CONNECTOR | E10: CONNECTOR | F10: 0 | G10: =2000+1000+4000 -> 7000 | I10: =F10+G10-H10 -> 7000 | J10: 2.5 | K10: =I10*J10 -> 17500
B11: CR18006 | C11: 6 | D11: 3 PIN PBT CONNECTOR | E11: CONNECTOR | F11: 0 | G11: =2400+1200+3800 -> 7400 | I11: =F11+G11-H11 -> 7400 | J11: 3.75 | K11: =I11*J11 -> 27750
B12: CR18007 | C12: 7 | D12: 1A, 250V Slow Blow | E12: FUSE | F12: 0 | G12: 4800 | I12: =F12+G12-H12 -> 4800 | J12: 2.5 | K12: =I12*J12 -> 12000
B13: CR18008 | C13: 8 | D13: 3.15A, 250V Slow Blow | E13: FUSE | F13: 0 | G13: =4000+400 -> 4400 | I13: =F13+G13-H13 -> 4400 | J13: 2.5 | K13: =I13*J13 -> 11000
J15: TOTAL | K15: =SUM(K6:K12) -> 57250

Sheet CAPACITOR
A2: CAPACITOR STORE STOCK
A4: RAWMATERIAL CODE | B4: CATAGARE NO | C4: SLNO | D4: PART NO | E4: DESCRIPTION | F4: PHY QTY | G4: RECEIPT | H4: ISSUE | I4: BALANCE | J4: UNIT PRICE | K4: AMOUNT
A5: VN0083CP04001 | B5: CP04001 | C5: 1 | D5: B32922C3104K6 | E5: CAPACITOR | I5: =F5+G5-H5 -> 0 | J5: 2.5 | K5: =I5*J5 -> 0
A6: VN0082CP04002 | B6: CP04002 | C6: 2 | D6: 0.1MF-275V.40/100/21 X2 15MM PITCH | E6: CAPACITOR | F6: 41 | I6: =F6+G6-H6 -> 41 | J6: 1 | K6: =I6*J6 -> 41
A7: VN0082CP04003 | B7: CP04003 | C7: 3 | D7: 0.01 MF/250V FFC CAPACITOR FFC | E7: CAPACITOR | F7: 85 | I7: =F7+G7-H7 -> 85 | J7: 1 | K7: =I7*J7 -> 85
A8: VN0083CP04004 | B8: CP04004 | C8: 4 | D8: P2G102K POLY 1KPF /400V | E8: CAPACITOR | F8: 0 | G8: =1000+5000 -> 6000 | H8: 1000 | I8: =F8+G8-H8 -> 5000 | J8: 0.8 | K8: =I8*J8 -> 4000
A9: VN0082CP04005 | B9: CP04005 | C9: 5 | D9: 33PF | E9: CAPACITOR | I9: =F9+G9-H9 -> 0 | J9: 1 | K9: =I9*J9 -> 0
A10: VN0082CP04006 | B10: CP04006 | C10: 6 | D10: CAP POLY BOX 0.22K 275V X2 YELLOW | E10: CAPACITOR(YELLOW) | F10: 125 | I10: =F10+G10-H10 -> 125 | J10: 2 | K10: =I10*J10 -> 250
A11: VN0082CP04007 | B11: CP04007 | C11: 7 | D11: CAPACITOR CERAMIC 103 PF 1KV | E11: DISC CAPACITOR | F11: =11600+202+161 -> 11963 | G11: =6000+40000+6000+4000 -> 56000 | H11: =30+702+1404+3000+15 -> 5151 | I11: =F11+G11-H11 -> 62812 | J11: 0.6 | K11: =I11*J11 -> 37687.2
A12: VN0082CP04008 | B12: CP04008 | C12: 8 | D12: CERAMIC DISC 470 PF / 50V / 20% | E12: DISC CAPACITOR | F12: 100 | I12: =F12+G12-H12 -> 100 | J12: 1 | K12: =I12*J12 -> 100
A13: VN0082CP04009 | B13: CP04009 | C13: 9 | D13: CAP CERAMIC DISC 102 ,1KV | E13: DISC CAPACITOR | F13: =683+90+18+52 -> 843 | I13: =F13+G13-H13 -> 843 | J13: 1 | K13: =I13*J13 -> 843
A14: VN0082CP04011 | B14: CP04010 | C14: 11 | D14: ELE.CAP 100MF/160V / 20% -85@C | E14: ELECTROLYTIC CAPACITOR | F14: 182 | I14: =F14+G14-H14 -> 182 | J14: 3.15 | K14: =I14*J14 -> 573.3
A15: VN0082CP04012 | B15: CP04011 | C15: 12 | D15: ELE.CAP 100uf/250v/ 20% -105@C | E15: ELECTROLYTIC CAPACITOR | F15: 75 | I15: =F15+G15-H15 -> 75 | J15: 3.15 | K15: =I15*J15 -> 236.25
A16: VN0082CP04013 | B16: CP04012 | C16: 13 | D16: ELE.CAP 10mf/250v/ 20% -85@C | E16: ELECTROLYTIC CAPACITOR | F16: 18 | I16: =F16+G16-H16 -> 18 | J16: 3 | K16: =I16*J16 -> 54
A17: VN0082CP04014 | B17: CP04013 | C17: 14 | D17: ELE.CAP 22uf/50v / 20% --105@C | E17: ELECTROLYTIC CAPACITOR | F17: =260+886+6 -> 1152 | G17: =2000+400+5000+16000 -> 23400 | H17: =1+400+1+1+2000+15 -> 2418 | I17: =F17+G17-H17 -> 22134 | J17: 0.55 | K17: =I17*J17 -> 12173.7
A18: VN0082CP04015 | B18: CP04014 | C18: 15 | D18: ELE.CAP 100uf/25v / 20% -105@C | E18: ELECTROLYTIC CAPACITOR | F18: 485 | G18: 5000 | I18: =F18+G18-H18 -> 5485 | J18: 0.78 | K18: =I18*J18 -> 4278.3
A19: VN0082CP04016 | B19: CP04015 | C19: 16 | D19: ELE.CAP 22MFD/400V / 20% --85@C | E19: ELECTROLYTIC CAPACITOR | F19: 5 | I19: =F19+G19-H19 -> 5 | J19: 3 | K19: =I19*J19 -> 15
A20: VN0082CP04017 | B20: CP04016 | C20: 17 | D20: ELE.CAP 22mf/400v / 20% --105@C | E20: ELECTROLYTIC CAPACITOR | F20: 35 | I20: =F20+G20-H20 -> 35 | J20: 3 | K20: =I20*J20 -> 105
A21: VN0082CP04018 | B21: CP04017 | C21: 18 | D21: ELE.CAP 100mf/25v/ 20% | E21: ELECTROLYTIC CAPACITOR | I21: =F21+G21-H21 -> 0 | J21: 3 | K21: =I21*J21 -> 0
A22: VN0082CP04019 | B22: CP04018 | C22: 19 | D22: ELE.CAP 22uf/50v/ 20% | E22: ELECTROLYTIC CAPACITOR | I22: =F22+G22-H22 -> 0 | J22: 3 | K22: =I22*J22 -> 0
A23: VN0082CP04020 | B23: CP04019 | C23: 20 | D23: ELE.CAP 470UF/25V/ 20% | E23: ELECTROLYTIC CAPACITOR | I23: =F23+G23-H23 -> 0 | J23: 4 | K23: =I23*J23 -> 0
A24: VN0082CP04021 | B24: CP04020 | C24: 21 | D24: ELE.CAP 1UF/50V/ 20% --105@C | E24: ELECTROLYTIC CAPACITOR | F24: 0 | G24: =16000+70 -> 16070 | I24: =F24+G24-H24 -> 16070 | J24: 0.78 | K24: =I24*J24 -> 12534.6
A25: VN0082CP04022 | B25: CP04021 | C25: 22 | D25: ELE.CAP 22uF/250V/ 20% --85@C | E25: ELECTROLYTIC CAPACITOR | F25: 49 | G25: 10000 | I25: =F25+G25-H25 -> 10049 | J25: 3.6 | K25: =I25*J25 -> 36176.4
A26: VN0009CP04023 | B26: CP04022 | C26: 23 | D26: 220nF/400V | E26: ELECTROLYTIC CAPACITOR | I26: =F26+G26-H26 -> 0 | J26: 2 | K26: =I26*J26 -> 0
A27: VN0009CP04024 | B27: CP04023 | C27: 24 | D27: 1nF/500V / 1206 | E27: SMD CAPACITERS | F27: 0 | G27: 5000 | I27: =F27+G27-H27 -> 5000 | J27: 1.3 | K27: =I27*J27 -> 6500
A28: VN0009CP04025 | B28: CP04024 | C28: 25 | D28: 470uF/63V / 20% --105@C | E28: ELECTROLYTIC CAPACITOR | F28: 0 | G28: 2500 | I28: =F28+G28-H28 -> 2500 | J28: 4.9 | K28: =I28*J28 -> 12250
A29: VN0009CP04026 | B29: CP04025 | C29: 26 | D29: CAP PLOY 0.047uF/275VAC/ 20% X2 | E29: BOX CAPACITOR | F29: 11 | G29: 5000 | H29: 11 | I29: =F29+G29-H29 -> 5000 | J29: 2.1 | K29: =I29*J29 -> 10500
A30: VN0009CP04027 | B30: CP04026 | C30: 27 | D30: CAP CERAMIC 2.2nF/275VAC/ 20% X1 Y1 | E30: DISC CAPACITOR | F30: 68 | G30: =400+2000+5000+6000+15000 -> 28400 | H30: =10+400+2000 -> 2410 | I30: =F30+G30-H30 -> 26058 | J30: 2.5 | K30: =I30*J30 -> 65145
B31: CP04027 | C31: 28 | D31: CAP POLYESTER 104J 400V | E31: POLY CAPACITOR | F31: 382 | G31: =2000+5000 -> 7000 | H31: =10+372+2000 -> 2382 | I31: =F31+G31-H31 -> 5000 | J31: 1.6 | K31: =I31*J31 -> 8000
B32: CP04028 | C32: 29 | D32: 0.022Mf /275V-X2 | E32: BOX CAPACITOR | G32: =400+2000 -> 2400 | H32: =400+2000 -> 2400 | I32: =F32+G32-H32 -> 0 | J32: 2.25 | K32: =I32*J32 -> 0
B33: CP04029 | C33: 30 | D33: 100nF(104) | F33: 0 | G33: 0 | H33: 0 | I33: 0 | J33: 0 | K33: 0
B34: CP04030 | C34: 31 | D34: 10uF/63V | F34: 0 | G34: 0 | H34: 0 | I34: 0 | J34: 0 | K34: 0
B35: CP04031 | C35: 32 | D35: 100nf/63V | F35: 0 | G35: 0 | H35: 0 | I35: 0 | J35: 0 | K35: 0
B36: CP04032 | C36: 33 | D36: 2.2uF/63V | F36: 0 | G36: 0 | H36: 0 | I36: 0 | J36: 0 | K36: 0
B37: CP04033 | C37: 34 | D37: 47Pf/50V-0805 | E37: CAP_EL_5_3 | F37: 0 | G37: 0 | H37: 0 | I37: 0 | J37: 0 | K37: 0
B38: CP04034 | C38: 35 | D38: 470/50 ELE CAP | E38: CAP_EL_5_4 | F38: 0 | G38: 0 | H38: 0 | I38: 0 | J38: 0 | K38: 0
B39: CP04035 | C39: 36 | D39: 1NF/1000V-0805 | E39: SMD CAPACITERS | F39: 0 | G39: 0 | H39: 0 | I39: 0 | J39: 0 | K39: 0
B40: CP04036 | C40: 37 | D40: 1MF/50V-0805 | E40: SMD CAPACITERS | F40: 0 | G40: 0 | H40: 0 | I40: 0 | J40: 0 | K40: 0
B41: CP04037 | C41: 38 | D41: 470/63 ELE CAP | E41: CAP_EL_5_4 | F41: 0 | G41: 0 | H41: 0 | I41: 0 | J41: 0 | K41: 0
B42: CP04038 | C42: 39 | D42: 10UF/250V | E42: CAP_EL_5_2 | F42: 0 | G42: 0 | H42: 0 | I42: 0 | J42: 0 | K42: 0
...

Sheet HEATSINK
A3: HEAT SINK STORE STOCK
A5: RAWMATERIAL CODE | B5: CATAGARE NO | C5: SLNO | D5: PART NO | E5: DESCRIPTION | F5: PHY QTY | G5: RECEIPT | H5: ISSUE | I5: BALANCE | J5: UNIT PRICE | K5: AMOUNT
A6: VN0009HS03001 | B6: HS03001 | C6: 1 | D6: HEAT SINK STRIP | E6: HEAT SINK | F6: 0 | I6: =F6+G6-H6 -> 0 | J6: 10 | K6: =I6*J6 -> 0
A7: VN0009HS03002 | B7: HS03002 | C7: 2 | D7: HEAT SINK COMPOND | E7: HEAT SINK COMPOND | F7: 0 | I7: =F7+G7-H7 -> 0 | J7: 30 | K7: =I7*J7 -> 0
A8: VN0009HS03003 | B8: HS03003 | C8: 3 | D8: HS-501 | E8: HEAT SINK | F8: 0 | I8: =F8+G8-H8 -> 0 | J8: 0 | K8: =I8*J8 -> 0
C9: 4 | D9: HEAT SINK U TYPE | E9: HEAT SINK | F9: 0 | G9: =10+32 -> 42 | I9: =F9+G9-H9 -> 42 | J9: 5 | K9: =I9*J9 -> 210
C10: 5
J11: TOTAL | K11: =SUM(K6:K10) -> 210

Sheet INDUCTOR
A3: INDUCTORE STORE STOCK
A5: RAWMATERIAL CODE | B5: CATAGARE NO | C5: SLNO | D5: PART NO | E5: DESCRIPTION | F5: PHY QTY | G5: RECEIPT | H5: ISSUE | I5: BALANCE | J5: UNIT PRICE | K5: AMOUNT
A6: VN0080IN08001 | B6: IN08001 | C6: 1 | D6: 3.3MH | E6: INDUCTOR | I6: =F6+G6-H6 -> 0 | J6: 1.32 | K6: =I6*J6 -> 0
A7: VN0043IN08002 | B7: IN08002 | C7: 2 | D7: 1mH AL 0510 | E7: INDUCTOR | F7: 11000 | H7: =20+20+800+2806+20+50+5+15+1000+4000+15 -> 8751 | I7: =F7+G7-H7 -> 2249 | J7: 0.91 | K7: =I7*J7 -> 2046.59
A8: VN0063IN08003 | B8: IN08003 | C8: 3 | D8: EE-16 INDUCTOR | E8: INDUCTOR | F8: =520+150 -> 670 | H8: =400+161 -> 561 | I8: =F8+G8-H8 -> 109 | J8: 7.5 | K8: =I8*J8 -> 817.5
A9: VN0080IN08004 | B9: IN08004 | C9: 4 | D9: 1 Mh | E9: INDUCTOR | I9: =F9+G9-H9 -> 0 | J9: 2.75 | K9: =I9*J9 -> 0
A10: VN0043IN08003 | B10: IN08005 | C10: 5 | D10: 2.2 Mh/300mA 10 X 12WL | E10: INDUCTOR | I10: =F10+G10-H10 -> 0 | J10: 7.5 | K10: =I10*J10 -> 0
A11: VN0063IN08004 | B11: IN08006 | C11: 6 | D11: 42v/240mA | E11: Transformer | I11: =F11+G11-H11 -> 0 | J11: 25 | K11: =I11*J11 -> 0
A12: VN0080IN08005 | B12: IN08007 | C12: 7 | D12: EE-16 TRNS 24/350 MA | E12: Transformer | F12: 140 | I12: =F12+G12-H12 -> 140 | J12: 12 | K12: =I12*J12 -> 1680
A13: VN0043IN08004 | B13: IN08008 | C13: 8 | D13: EE-20 TRNS 42/360 10PIN ( MT11448 ) | E13: Transformer | F13: 0 | G13: =1560+2000 -> 3560 | I13: =F13+G13-H13 -> 3560 | J13: 16 | K13: =I13*J13 -> 56960
B14: IN08009 | C14: 9 | D14: EE-16 TRNS 24V/360MA | E14: Transformer | F14: 360 | I14: =F14+G14-H14 -> 360 | J14: 12 | K14: =I14*J14 -> 4320
B15: IN08010 | C15: 10 | D15: EE-16 TRANS 5W-DL 2.0 | E15: Transformer | F15: 650 | I15: =F15+G15-H15 -> 650 | J15: 10 | K15: =I15*J15 -> 6500
B16: IN08011 | C16: 11 | D16: EE-16 MT 1584 | E16: Transformer | F16: =81+81 -> 162 | I16: =F16+G16-H16 -> 162 | J16: 10 | K16: =I16*J16 -> 1620
B17: IN08012 | C17: 12 | D17: INDUCTOR 0.65Mh | E17: INDUCTOR | F17: 10 | I17: =F17+G17-H17 -> 10 | J17: 20 | K17: =I17*J17 -> 200
B18: IN08013 | C18: 13 | D18: INDUCTOR 0.68Mh | E18: INDUCTOR | F18: 5 | I18: =F18+G18-H18 -> 5 | J18: 20 | K18: =I18*J18 -> 100
B19: IN08014 | C19: 14 | D19: INDUCTOR 2.4mH --EE16 | E19: INDUCTOR | G19: 1443 | H19: =1400 -> 1400 | I19: =F19+G19-H19 -> 43 | J19: 7.5 | K19: =I19*J19 -> 322.5
B20: IN08015 | C20: 15 | D20: TRANSFORMER EE16-24V/350MA -MT15942 | E20: Transformer | F20: 0 | G20: =500+500 -> 1000 | H20: =500+6 -> 506 | I20: =F20+G20-H20 -> 494 | J20: 12 | K20: =I20*J20 -> 5928
B21: IN08017 | C21: 16 | D21: TRANSFORMER EE13 --ETR | E21: Transformer | F21: 0 | G21: =1000+1000 -> 2000 | I21: =F21+G21-H21 -> 2000 | J21: 9 | K21: =I21*J21 -> 18000
B22: IN08016 | C22: 17 | D22: EE16-4.5MH | E22: Transformer
B23: IN08017 | C23: 18 | D23: EE13 | E23: Transformer
B24: IN08018 | C24: 19 | D24: SK1.25MH | E24: Transformer
B25: IN08019 | C25: 20 | D25: 2.2mH | E25: Transformer
B26: IN08020 | C26: 21 | D26: EE25 H | E26: Transformer
B27: IN08021 | C27: 22 | D27: ETR-EE13 HORIZONTAL 2.2~2.3mH TRANSFORMER | E27: Transformer
B28: IN08022 | C28: 23 | D28: INDUCTOR 1MH / 300mA size 8x10 | E28: inductor | F28: 0 | G28: =1000+2000+4500 -> 7500 | I28: =F28+G28-H28 -> 7500 | J28: 5 | K28: 5000
B29: IN08023 | C29: 24 | D29: EE-25 TRANSFORMER MT 4512 | E29: Transformer
B30: IN08024 | C30: 25 | D30: 2.4MH /0.7A/ 12 X 15 | E30: INDUCTOR
B31: IN08025 | C31: 26 | D31: EF20 H MT- 10031 | E31: Transformer
C32: 27 | D32: INDUCTOR 3mH -EE16 | E32: INDUCTOR | G32: 1050 | I32: =F32+G32-H32 -> 1050 | J32: 7.5 | K32: =I32*J32 -> 7875
C33: 28 | D33: TRANSFORMER EE16-24V/350MA -MT15942 | H33: =E33+F33-G33 -> 0 | I33: =F33+G33-H33 -> 0 | J33: 2.75
C34: 29 | D34: EE20 - TRANSFORMER 10031 | E34: Transformer | G34: =1000+1000 -> 2000 | I34: =F34+G34-H34 -> 2000 | J34: 16 | K34: =I34*J34 -> 32000
C35: 30 | D35: EE16 - TRANSFORMER 15947 | E35: Transformer | F35: 0 | G35: 2000 | I35: =F35+G35-H35 -> 2000 | J35: 12 | K35: =I35*J35 -> 24000
J36: TOTAL | K36: =SUM(K6:K28) -> 103494.59

Sheet MOSFET
A4: MOSFET STORE STOCK
A6: RAWMATERIAL CODE | B6: CATAGARE NO | C6: SLNO | D6: PART NO | E6: DESCRIPTION | F6: PHY QTY | G6: RECEIPT | H6: ISSUE | I6: BALANCE | J6: UNIT PRICE | K6: AMOUNT | L6: As per physical count
A7: SM0105MF02001 | B7: MF02001 | C7: 1 | D7: SMUA2121 A 207 1P | E7: MOSFET | I7: =F7+G7-H7 -> 0 | J7: 15 | K7: =I7*J7 -> 0
A8: SM0105MF02002 | B8: MF02002 | C8: 2 | D8: 5N50 | E8: MOSFET | I8: =F8+G8-H8 -> 0 | J8: 17.4 | K8: =I8*J8 -> 0
A9: SM0105MF02003 | B9: MF02003 | C9: 3 | D9: MSU2NGO | E9: MOSFET | I9: =F9+G9-H9 -> 0 | J9: 5.52 | K9: =I9*J9 -> 0
A10: SM0105MF02004 | B10: MF02004 | C10: 4 | D10: SM4N60 | E10: MOSFET | F10: 2409 | G10: =250+5000+6973+4000+23000 -> 39223 | H10: =10+12+702+65+1000+8+5 -> 1802 | I10: =F10+G10-H10 -> 39830 | J10: 11.15 | K10: =I10*J10 -> 444104.5
A11: SM0105MF02005 | B11: MF02005 | C11: 5 | D11: SMN-2N60 | E11: MOSFET | F11: =36000+96+30+131+1875+1950 -> 40082 | H11: =400+2000 -> 2400 | I11: =F11+G11-H11 -> 37682 | J11: 12 | K11: =I11*J11 -> 452184 | L11: 37725
A12: VN0009MF02006 | B12: MF02006 | C12: 6 | D12: 10N80-FSC | E12: MOSFET | I12: =F12+G12-H12 -> 0 | J12: 28 | K12: =I12*J12 -> 0
B13: MF02007 | C13: 7 | D13: IRFZ44N | E13: MOSFET | I13: =F13+G13-H13 -> 0 | K13: =I13*J13 -> 0
B14: MF02008 | C14: 8 | D14: 12N90 | E14: MOSFET
B15: MF02009 | C15: 9 | D15: 4N80T.TO-220 | E15: MOSFET
B16: MF02010 | C16: 8 | D16: 4N60C | E16: MOSFET | F16: 9 | H16: 7 | I16: =F16+G16-H16 -> 2 | J16: 38 | K16: =I16*J16 -> 76
J17: TOTAL | K17: =SUM(K7:K15) -> 896288.5

Sheet DRIVER
D1: SEMTRONICS MICROSYSTEMS PVT LTD
D2: G.G STOCK AS ON 31.12.2013
A3: DRIVER STORE STOCK
J4: 13.01.2014
A5: RAWMATERIAL CODE | B5: CATAGARE NO | C5: SLNO | D5: PART NO | E5: DESCRIPTION | F5: PHY QTY | G5: 31.12.13 | H5: RECEIPT | I5: ISSUE | J5: BALANCE | K5: UNIT PRICE | L5: AMOUNT
A6: SM0105DR13001 | B6: DR13001 | C6: 1 | D6: E27-SEM V1 | E6: DRIVER | F6: 188 | G6: 188 | J6: =G6+H6-I6 -> 188 | K6: 80 | L6: =J6*K6 -> 15040
A7: SM0105DR13002 | B7: DR13002 | C7: 2 | D7: 3 WATT DC DC | E7: DRIVER | F7: 0 | J7: =G7+H7-I7 -> 0 | K7: 70 | L7: =J7*K7 -> 0
A8: SM0105DR13003 | B8: DR13003 | C8: 3 | D8: ISOLATED DOWN LIGHT DRIVER | E8: DRIVER | F8: 0 | J8: =G8+H8-I8 -> 0 | K8: 180 | L8: =J8*K8 -> 0
A9: SM0105DR13004 | B9: DR13004 | C9: 4 | D9: T8 -18 Watt ISOLATED TUBE LIGHT DRIVER | E9: DRIVER | F9: 1450 | G9: 1450 | J9: =G9+H9-I9 -> 1450 | K9: 105 | L9: =J9*K9 -> 152250
A10: SM0105DR13005 | B10: DR13005 | C10: 5 | D10: T8 -24 Watt ISOLATED TUBE LIGHT DRIVER | E10: DRIVER | F10: 932 | G10: 730 | I10: 100 | J10: =G10+H10-I10 -> 630 | K10: 110 | L10: =J10*K10 -> 69300
A11: SM0105DR13006 | B11: DR13006 | C11: 6 | D11: 20 WATT AC DC LED DRIVER | E11: DRIVER | F11: 0 | J11: =G11+H11-I11 -> 0 | K11: 300 | L11: =J11*K11 -> 0
A12: SM0105DR13007 | B12: DR13007 | C12: 7 | D12: 8-12 WATT 350mA DRIVER | E12: DRIVER | F12: 0 | J12: =G12+H12-I12 -> 0 | K12: 60 | L12: =J12*K12 -> 0
A13: SM0105DR13008 | B13: DR13008 | C13: 8 | D13: 10-15 WATT 700mA DRIVER | E13: DRIVER | F13: 0 | J13: =G13+H13-I13 -> 0 | K13: 300 | L13: =J13*K13 -> 0
A14: SM0105DR13009 | B14: DR13009 | C14: 9 | D14: 15-20 WATT 350mA DRIVER B | E14: DRIVER | F14: 102 | G14: 112 | J14: =G14+H14-I14 -> 112 | K14: 60 | L14: =J14*K14 -> 6720
A15: SM0105DR13010 | B15: DR13010 | C15: 10 | D15: 12-18WATT 350mA DRIVER | E15: DRIVER | F15: 0 | G15: 193 | J15: =G15+H15-I15 -> 193 | K15: 300 | L15: =J15*K15 -> 57900
A16: SM0105DR13011 | B16: DR13011 | C16: 11 | D16: 1-3 WATT 350mA DRIVER | E16: DRIVER | F16: 5030 | G16: 3846 | I16: =6+100+5+1+2+10+20 -> 144 | J16: 0 | K16: 55 | L16: =J16*K16 -> 0
A17: SM0105DR13012 | B17: DR13012 | C17: 12 | D17: 7-12WATT 350mA DRIVER A | E17: DRIVER | F17: 5 | G17: 680 | I17: 0 | J17: 0 | K17: 114 | L17: =J17*K17 -> 0
A18: SM0105DR13013 | B18: DR13013 | C18: 13 | D18: 4-7 WATT 350mA DRIVER A | E18: DRIVER | F18: 3 | H18: 50 | I18: 50 | J18: =G18+H18-I18 -> 0 | K18: 74 | L18: =J18*K18 -> 0
A19: SM0105DR13014 | B19: DR13014 | C19: 14 | D19: 30-35 WATT 600mA DRIVER | E19: DRIVER | F19: 0 | G19: 13 | J19: =G19+H19-I19 -> 13 | K19: 445 | L19: =J19*K19 -> 5785
A20: SM0105DR13015 | B20: DR13015 | C20: 15 | D20: 12-18WATT 700mA DRIVER | E20: DRIVER | F20: 0 | J20: =G20+H20-I20 -> 0 | K20: 300 | L20: =J20*K20 -> 0
A21: SM0105DR13016 | B21: DR13016 | C21: 16 | D21: 2-8 watt 350mA DRIVER | E21: DRIVER | F21: 0 | J21: =G21+H21-I21 -> 0 | K21: 55 | L21: =J21*K21 -> 0
A22: SM0105DR13017 | B22: DR13017 | C22: 17 | D22: 20-25WATT 350mA DRIVER | E22: DRIVER | F22: 0 | G22: 139 | J22: =G22+H22-I22 -> 139 | K22: 350 | L22: =J22*K22 -> 48650
A23: SM0105DR13018 | B23: DR13018 | C23: 18 | D23: E27 4.5 VER | E23: DRIVER | F23: 1900 | G23: 299 | J23: 0 | K23: 128 | L23: =J23*K23 -> 0
A24: SM0105DR13019 | B24: DR13019 | C24: 19 | D24: T8 TUBE LIGHT DRIVER 4.5 VER | E24: DRIVER | F24: 200 | J24: 150 | K24: 105 | L24: =J24*K24 -> 15750
A25: SM0105DR13020 | B25: DR13020 | C25: 20 | D25: T8 TUBE LIGHT DRIVER 4.2 VER | E25: DRIVER | F25: 15 | G25: 190 | J25: =G25+H25-I25 -> 190 | K25: 90 | L25: =J25*K25 -> 17100
A26: SM0105DR13021 | B26: DR13021 | C26: 21 | D26: T8 TUBE LIGHT DRIVER 5.4 VER | E26: DRIVER | F26: 56 | H26: =100+50+182 -> 332 | I26: =100+50+100 -> 250 | J26: 0 | K26: 105 | L26: =J26*K26 -> 0
A27: SM0105DR13022 | B27: DR13022 | C27: 22 | D27: 6 WATT DC DC | E27: DRIVER | F27: 23 | J27: =G27+H27-I27 -> 0 | K27: 75 | L27: =J27*K27 -> 0
A28: SM0105DR13023 | B28: DR13023 | C28: 23 | D28: E27-SEM 6W | E28: DRIVER | F28: 59 | J28: =G28+H28-I28 -> 0 | K28: 80 | L28: =J28*K28 -> 0
A29: SM0105DR13024 | B29: DR13024 | C29: 24 | D29: E27-SEM 8W | E29: DRIVER | F29: 140 | J29: =G29+H29-I29 -> 0 | K29: 80 | L29: =J29*K29 -> 0
A30: SM0105DR13025 | B30: DR13025 | C30: 25 | D30: E27-SEM 2W | E30: DRIVER | F30: 100 | J30: =G30+H30-I30 -> 0 | K30: 75 | L30: =J30*K30 -> 0
A31: SM0105DR13026 | B31: DR13026 | C31: 26 | D31: E27-CS-EM1 MISSING COMPONENTS | E31: DRIVER | F31: 150 | J31: =G31+H31-I31 -> 0 | K31: 35 | L31: =J31*K31 -> 0
A32: SM0105DR13027 | B32: DR13027 | C32: 27 | D32: TUBE LIGHT 4.4 VER | E32: DRIVER | F32: 0 | J32: =G32+H32-I32 -> 0 | K32: 105 | L32: =J32*K32 -> 0
A33: SM0105DR13028 | B33: DR13028 | C33: 28 | D33: 4-7 WATT 350mA DRIVER B | E33: DRIVER | F33: 1406 | G33: 1312 | I33: 175 | J33: 0 | K33: 74 | L33: =J33*K33 -> 0
A34: SM0105DR13029 | B34: DR13029 | C34: 29 | D34: 20-25WATT 700mA DRIVER | E34: DRIVER | F34: 0 | J34: =G34+H34-I34 -> 0 | K34: 350 | L34: =J34*K34 -> 0
A35: SM0105DR13030 | B35: DR13030 | C35: 30 | D35: 1-3 WATT 1mA DRIVER | E35: DRIVER | F35: 26 | G35: 23 | J35: =G35+H35-I35 -> 23 | K35: 55 | L35: =J35*K35 -> 1265
A36: SM0105DR13031 | B36: DR13031 | C36: 31 | D36: 2-6 watt 350mA DRIVER | E36: DRIVER | F36: 60 | G36: 63 | J36: =G36+H36-I36 -> 63 | K36: 55 | L36: =J36*K36 -> 3465
A37: SM0105DR13032 | B37: DR13032 | C37: 32 | D37: 1-3 WATT 700mA DRIVER | E37: DRIVER | F37: 0 | J37: =G37+H37-I37 -> 0 | K37: 55 | L37: =J37*K37 -> 0
A38: SM0105DR13033 | B38: DR13033 | C38: 33 | D38: 7-12WATT 300mA DRIVER B | E38: DRIVER | F38: 152 | G38: 191 | J38: 0 | K38: 114 | L38: =J38*K38 -> 0
A39: SM0105DR13034 | B39: DR13034 | C39: 34 | D39: 8-10 WATT 150mA DRIVER | E39: DRIVER | F39: 0 | J39: =G39+H39-I39 -> 0 | K39: 55 | L39: =J39*K39 -> 0
A40: SM0105DR13035 | B40: DR13035 | C40: 35 | D40: 40-45 WATT 1.05mA DRIVER | E40: DRIVER | F40: 1 | J40: =G40+H40-I40 -> 0 | K40: 145 | L40: =J40*K40 -> 0
...

Sheet FG
A1: FINISHED GOODS STOCK
A3: PRODUCT CODE | B3: CATAGARE NO | C3: SLNO | D3: PART NO | E3: DESCRIPTION | F3: PHY QTY | G3: RECEIPT | H3: ISSUE | I3: BALANCE | J3: UNIT PRICE | K3: AMOUNT
A4: SM0105FG16001 | B4: FG16001 | C4: 1 | D4: 65 WATT 3.2 Amp ADAPTORE | E4: F.G | I4: =F4+G4-H4 -> 0 | J4: 100 | K4: =I4*J4 -> 0
A5: SM0105FG16002 | B5: FG16002 | C5: 2 | D5: PANAL LIGHT | E5: F.G | I5: =F5+G5-H5 -> 0 | J5: 1000 | K5: =I5*J5 -> 0
A6: SM0105FG16003 | B6: FG16003 | C6: 3 | D6: DOWN LIGHT-15LED 6WATT | E6: DOWN LIGHT | I6: =F6+G6-H6 -> 0 | J6: 1200 | K6: =I6*J6 -> 0
A7: SM0105FG16004 | B7: FG16004 | C7: 4 | D7: TUBE LIGHT - 2FEET (RETROFIT) | E7: TUBE LIGHT | G7: =1+2+10 -> 13 | H7: =1+7 -> 8 | I7: =F7+G7-H7 -> 5 | J7: 750 | K7: =I7*J7 -> 3750
A8: SM0105FG16005 | B8: FG16005 | C8: 5 | D8: TUBE LIGHT - 4FEET RETROFIT-280 LEDS | E8: TUBE LIGHT | F8: 0 | G8: =2+10+1+8+20+40 -> 81 | H8: 1 | I8: 2380 | J8: 1100 | K8: =I8*J8 -> 2618000
A9: SM0105FG16006 | B9: FG16006 | C9: 6 | D9: CDL3 WATT | E9: DOWN LIGHT | F9: 1116 | H9: =20+1+216+346 -> 583 | I9: =F9+G9-H9 -> 533 | J9: 395 | K9: =I9*J9 -> 210535
A10: SM0105FG16007 | B10: FG16007 | C10: 7 | D10: CDL5 WATT (MW) | E10: DOWN LIGHT | F10: 841 | G10: =90+36 -> 126 | H10: =1+216 -> 217 | I10: =F10+G10-H10 -> 750 | J10: 530 | K10: =I10*J10 -> 397500
A11: SM0105FG16008 | B11: FG16008 | C11: 8 | D11: CDL10 WATT ( MW) | E11: DOWN LIGHT | F11: 1240 | G11: =240+2 -> 242 | H11: =2+2+1+504 -> 509 | I11: 680 | J11: 962 | K11: =I11*J11 -> 654160
A12: SM0105FG16009 | B12: FG16009 | C12: 9 | D12: CDL15 WATT ( MW) | E12: DOWN LIGHT | F12: 1382 | G12: =160+2 -> 162 | H12: =20+18+1+552 -> 591 | I12: 560 | J12: 1180 | K12: =I12*J12 -> 660800
A13: SM0105FG16010 | B13: FG16010 | C13: 10 | D13: BULB 3WATT | E13: BULB | G13: =25+4+1 -> 30 | H13: 25 | I13: 15 | J13: 245 | K13: =I13*J13 -> 3675
A14: SM0105FG16011 | B14: FG16011 | C14: 11 | D14: BULB 5WATT | E14: BULB | G14: =25+120 -> 145 | H14: 25 | I14: =F14+G14-H14 -> 120 | J14: 330 | K14: =I14*J14 -> 39600
A15: SM0105FG16012 | B15: FG16012 | C15: 12 | D15: BULB 7WATT | E15: BULB | G15: =25+60 -> 85 | H15: 25 | I15: =F15+G15-H15 -> 60 | J15: 672 | K15: =I15*J15 -> 40320
A16: SM0105FG16013 | B16: FG16013 | C16: 13 | D16: CDLA6 WATT | E16: TUBE LIGHT | I16: =F16+G16-H16 -> 0 | J16: 600 | K16: =I16*J16 -> 0
A17: SM0105FG16014 | B17: FG16014 | C17: 14 | D17: CDLA3 WATT | E17: TUBE LIGHT | I17: =F17+G17-H17 -> 0 | J17: 400 | K17: =I17*J17 -> 0
A18: SM0105FG16015 | B18: FG16015 | C18: 15 | D18: TUBE LIGHT - 1FEET | E18: TUBE LIGHT | F18: 0 | G18: 1 | H18: 1 | I18: =F18+G18-H18 -> 0 | J18: 750 | K18: =I18*J18 -> 0
A19: SM0007FG16016 | B19: FG16016 | C19: 16 | D19: RGB LED UNDER WATER LIGHT | E19: SPOT LIGHT | I19: =F19+G19-H19 -> 0 | J19: 770 | K19: =I19*J19 -> 0
A20: SM0105FG16017 | B20: FG16017 | C20: 17 | D20: CDL- 5 Watt (WW) | E20: DOWN LIGHT | I20: 0 | J20: 550 | K20: =I20*J20 -> 0
A21: SM0105FG16018 | B21: FG16018 | C21: 18 | D21: CDL- 10 Watt (WW) | E21: DOWN LIGHT | F21: 0 | G21: 0 | H21: 0 | I21: 152 | J21: 900 | K21: =I21*J21 -> 136800
A22: SM0105FG16019 | B22: FG16019 | C22: 19 | D22: CDL- 15 Watt (WW) | E22: DOWN LIGHT | I22: 102 | J22: 1200 | K22: =I22*J22 -> 122400
A23: SM0007FG16020 | B23: FG16020 | C23: 20 | D23: Tube Light-2Ft 50 LED | E23: TUBE LIGHT | F23: 0 | G23: =1+5 -> 6 | H23: =1+5 -> 6 | I23: =F23+G23-H23 -> 0 | J23: 900 | K23: =I23*J23 -> 0
A24: SM0105FG16021 | B24: FG16021 | C24: 21 | D24: Tube Light-2Ft 50 LED(WW) | E24: TUBE LIGHT | G24: 1 | H24: 1 | I24: =F24+G24-H24 -> 0 | J24: 900 | K24: =I24*J24 -> 0
A25: SM0105FG16022 | B25: FG16022 | C25: 22 | D25: TL4FT RECTROFIT 100LED | E25: TUBE LIGHT | I25: =F25+G25-H25 -> 0 | J25: 0 | K25: =I25*J25 -> 0
A26: SM0105FG16023 | B26: FG16023 | C26: 23 | D26: TL4FT INTEGREATED 100LED (WW) | E26: TUBE LIGHT | F26: 0 | G26: =1+4+7 -> 12 | H26: =1+4+5 -> 10 | I26: 0 | J26: 1200 | K26: =I26*J26 -> 0
A27: SM0105FG16024 | B27: FG16024 | C27: 24 | D27: SPOT LIGHT- 3 Watt ME BOM | E27: SPOT LIGHT | F27: 180 | I27: =F27+G27-H27 -> 180 | J27: 450 | K27: =I27*J27 -> 81000
A28: SM0105FG16025 | B28: FG16025 | C28: 25 | D28: CDL- 6 Watt ME BOM | E28: DOWN LIGHT | I28: =F28+G28-H28 -> 0 | J28: 550 | K28: =I28*J28 -> 0
A29: SM0105FG16026 | B29: FG16026 | C29: 26 | D29: SPOT LIGHT- 6 Watt ME BOM | E29: SPOT LIGHT | F29: 238 | I29: 156 | J29: 550 | K29: =I29*J29 -> 85800
A30: SM0105FG16027 | B30: FG16027 | C30: 27 | D30: CL-10 WATT 150 LED'S | E30: CEALING LIGHT | I30: =F30+G30-H30 -> 0 | J30: 1200 | K30: =I30*J30 -> 0
A31: SM0105FG16028 | B31: FG16028 | C31: 28 | D31: 15 WATT SQUARE DOWN LIGHT | E31: DOWN LIGHT | F31: 16 | H31: =2+14 -> 16 | I31: =F31+G31-H31 -> 0 | J31: 1300 | K31: =I31*J31 -> 0
A32: SM0105FG16029 | B32: FG16029 | C32: 29 | D32: CDL- 3 Watt (WW) | E32: DOWN LIGHT | I32: 31 | J32: 395 | K32: =I32*J32 -> 12245
A33: SM0105FG16030 | B33: FG16030 | C33: 30 | D33: SPOT LIGHT 30WATT | E33: DOWN LIGHT | I33: =F33+G33-H33 -> 0 | J33: 0 | K33: =I33*J33 -> 0
A34: SM0105FG16031 | B34: FG16031 | C34: 31 | D34: DOWN LIGHT 2 X 2 | E34: DOWN LIGHT | I34: =F34+G34-H34 -> 0 | J34: 0 | K34: =I34*J34 -> 0
A35: SM0105FG16032 | B35: FG16032 | C35: 32 | D35: FLOOD LIGHT 20 WATT | E35: DOWN LIGHT | I35: =F35+G35-H35 -> 0 | J35: 0 | K35: =I35*J35 -> 0
A36: SM0105FG16033 | B36: FG16033 | C36: 33 | D36: STREET LIGHT 72 WATT | E36: DOWN LIGHT | I36: =F36+G36-H36 -> 0 | J36: 0 | K36: =I36*J36 -> 0
A37: SM0105FG16034 | B37: FG16034 | C37: 34 | D37: TL4FT RECTROFIT 100LED (MW) | E37: TUBE LIGHT | G37: =10+50+2+3+100+30+5+3 -> 203 | H37: =3+30+10+30+3+4+100+2+21 -> 203 | I37: 0 | J37: 1200 | K37: =I37*J37 -> 0
A38: SM0105FG16035 | B38: FG16035 | C38: 35 | D38: TUBELIGHT 3 FEET RETROFIT | E38: TUBE LIGHT | F38: 0 | G38: 1 | H38: 1 | I38: =F38+G38-H38 -> 0 | J38: 800 | K38: =I38*J38 -> 0
J39: TOTAL | K39: =SUM(K4:K38) -> 5066585

Sheet MOV
A3: MOV STORE STOCK
A5: RAWMATERIAL CODE | B5: CATAGARE NO | C5: SLNO | D5: PART NO | E5: DESCRIPTION | F5: PHY QTY | G5: RECEIPT | H5: ISSUE | I5: BALANCE | J5: UNIT PRICE | K5: AMOUNT
A6: VN0083MOV11001 | B6: MOV11001 | C6: 1 | D6: 440/14 | E6: MOV | F6: 30 | I6: =F6+G6-H6 -> 30 | J6: 2.3 | K6: =I6*J6 -> 69
A7: VN0083MOV11002 | B7: MOV11002 | C7: 2 | D7: 222M/400V | E7: MOV | I7: =F7+G7-H7 -> 0 | J7: 3 | K7: =I7*J7 -> 0
A8: VN0083MOV11003 | B8: MOV11003 | C8: 3 | D8: 14D471K(300/14) | E8: MOV | F8: =471+616 -> 1087 | G8: =1750+1000+1500+3500+3000 -> 10750 | H8: =10+10+400+2+702+1000+1+1600+5+15 -> 3745 | I8: =F8+G8-H8 -> 8092 | J8: 3.25 | K8: =I8*J8 -> 26299
A9: VN0083THM11004 | B9: THM11004 | C9: 4 | D9: 10D9 | E9: THERMISTER | F9: =1500+500 -> 2000 | I9: =F9+G9-H9 -> 2000 | J9: 2.85 | K9: =I9*J9 -> 5700
A10: VN0083MOV11005 | B10: MOV11005 | C10: 5 | D10: 10D471K(300/10) | E10: MOV | F10: =471 -> 471 | G10: =12000+4000+1000+4000 -> 21000 | I10: =F10+G10-H10 -> 21471 | J10: 2.9 | K10: =I10*J10 -> 62265.9
B11: MOV11006 | C11: 6 | D11: 7D471K(300/14) | E11: MOV | J11: 2.9
B12: MOV11007 | C12: 6 | D12: MOV 20D/511K | E12: MOV | F12: 22 | H12: 2 | I12: =F12+G12-H12 -> 20 | J12: 4 | K12: =I12*J12 -> 80
B13: MOV11008 | C13: 7 | D13: MOV 07D/471K | E13: MOV | F13: 63 | G13: 3000 | I13: 2000 | J13: 3 | K13: =I13*J13 -> 6000
B14: MOV11009 | C14: 8 | D14: MOV 510/14 | E14: MOV | F14: 14 | I14: =F14+G14-H14 -> 14 | J14: 4.5 | K14: =I14*J14 -> 63
B15: THM11010 | C15: 10 | D15: NTC/RES_2W | E15: THERMISTER
B16: CR18007 | C16: 9 | D16: FUSE 1AMPS FAST BLOWAXIAL TYPE 5X20 | E16: FUSE | F16: 0 | G16: 10000 | H16: 200 | I16: =F16+G16-H16 -> 9800 | J16: 2.75 | K16: =I16*J16 -> 26950
J17: TOTAL | K17: =SUM(K6:K16) -> 127426.9

Sheet WIRE
A3: WIRE STORE STOCK
A5: RAWMATERIAL CODE | B5: CATAGARE NO | C5: SLNO | D5: PART NO | E5: DESCRIPTION | F5: PHY QTY | G5: RECEIPT | H5: ISSUE | I5: BALANCE | J5: UNIT PRICE | K5: AMOUNT
A6: VN0018WR12001 | B6: WR12001 | C6: 1 | D6: 14 Stands Black Wire (Bundle) | E6: Wire | F6: 13 | G6: 12 | H6: =1+2 -> 3 | I6: =F6+G6-H6 -> 22 | J6: 190 | K6: =I6*J6 -> 4180
A7: VN0018WR12002 | B7: WR12002 | C7: 2 | D7: 14 Stands Red Wire (Bundle) | E7: Wire | F7: 30 | G7: 13 | I7: =F7+G7-H7 -> 43 | J7: 190 | K7: =I7*J7 -> 8170
B8: WR12003 | C8: 3 | D8: 19 StrandsTEFLON WIRE | E8: WIRE | F8: 0 | G8: =10+10 -> 20 | H8: =1+2+4+1+1+1+2 -> 12 | I8: =F8+G8-H8 -> 8 | J8: 975 | K8: =I8*J8 -> 7800
B9: WR12004 | C9: 4 | D9: 19 stands tefflon wire Red | E9: Wire
B10: WR12005 | C10: 5 | D10: 19 stands tefflon wire Black | E10: Wire
J12: TOTAL | K12: =SUM(K6:K11) -> 20150

Sheet ASSACERIES
A3: ASSAACERIES STORE STOCK
A5: RAWMATERIAL CODE | B5: CATAGARE NO | C5: SLNO | D5: PART NO | E5: DESCRIPTION | F5: PHY QTY | G5: RECEIPT | H5: ISSUE | I5: BALANCE | J5: UNIT PRICE | K5: AMOUNT
A6: VN0051EQ10001 | B6: EQ10001 | C6: 1 | D6: GE 2000 | E6: SILENT | F6: 0 | I6: =F6+G6-H6 -> 0 | J6: 150 | K6: =I6*J6 -> 0
A7: VN0009EQ10002 | B7: EQ10002 | C7: 2 | D7: V20-C/1+NPE,320V | E7: SWITCH | F7: 0 | I7: =F7+G7-H7 -> 0 | J7: 5 | K7: =I7*J7 -> 0
A8: VN0009EQ10003 | B8: EQ10003 | C8: 3 | D8: TNR-C20 | E8: SWITCH | I8: =F8+G8-H8 -> 0 | J8: 5 | K8: =I8*J8 -> 0
A9: VN0051EQ10002 | B9: EQ10004 | C9: 4 | D9: Cello Tape | E9: TAPE | I9: =F9+G9-H9 -> 0 | J9: 38 | K9: =I9*J9 -> 0
A10: VN0009EQ10004 | B10: EQ10005 | C10: 5 | D10: Packing Tape | E10: 2" 50mm Length, Brown Tape | I10: 5 | J10: 38 | K10: =I10*J10 -> 190
A11: VN0093EQ10006 | B11: EQ10006 | C11: 6 | D11: M3 x 6.5 mm Self Tap Screw | E11: Screw | I11: =F11+G11-H11 -> 0 | J11: 2 | K11: =I11*J11 -> 0
A12: VN0045EQ10007 | B12: EQ10007 | C12: 7 | D12: F.G.SLEEVING Nonshinkable Sleeve (4MM-WHITE) | E12: Nonshinkable Sleeve | I12: =F12+G12-H12 -> 0 | J12: 200 | K12: =I12*J12 -> 0
A13: VN0112EQ10008 | B13: EQ10008 | C13: 8 | D13: FIBRE GLASS SLEEVE 3 mm Sleeve | E13: Shinkable Sleeve | G13: 100 | H13: 100 | I13: =F13+G13-H13 -> 0 | J13: 1.65 | K13: =I13*J13 -> 0
A14: VN0023EQ10009 | B14: EQ10009 | C14: 9 | D14: Anabond | E14: Thermal Adhesive | G14: 5 | I14: =F14+G14-H14 -> 5 | J14: 80 | K14: =I14*J14 -> 400 | L14: SAW INVOICE
A15: VN0073EQ10010 | B15: EQ10010 | C15: 10 | D15: Solder lead | E15: Tin Lead | I15: =F15+G15-H15 -> 0 | J15: 675 | K15: =I15*J15 -> 0
A16: VN0073EQ10011 | B16: EQ10011 | C16: 11 | D16: Solder flux | E16: Ammonium Chlride or Rosin | I16: =F16+G16-H16 -> 0 | J16: 500 | K16: =I16*J16 -> 0
A17: VN0073EQ10012 | B17: EQ10012 | C17: 12 | D17: I P A | E17: ISO PROPYLE ALCHOCOL | F17: 0 | G17: 5 | I17: =F17+G17-H17 -> 5 | J17: 95 | K17: =I17*J17 -> 475
A18: VN0002EQ10013 | B18: EQ10013 | C18: 13 | D18: Cotton waste | E18: White Cotton waste | I18: 2 | J18: 100 | K18: =I18*J18 -> 200
A19: VN0113EQ10014 | B19: EQ10014 | C19: 14 | D19: Packing Box | E19: 195x195x195mm | I19: =F19+G19-H19 -> 0 | K19: =I19*J19 -> 0
A20: VN0041EQ10015 | B20: EQ10015 | C20: 15 | D20: 384 Locktite | E20: Locktite | I20: =F20+G20-H20 -> 0 | J20: 1150 | K20: =I20*J20 -> 0
A21: VN0045EQ10016 | B21: EQ10016 | C21: 16 | D21: Polythine Sheet | E21: Polyester Film (5Mil-milky) | I21: =F21+G21-H21 -> 0 | J21: 300 | K21: =I21*J21 -> 0
A22: VN0023EQ10017 | B22: EQ10017 | C22: 17 | D22: 203 Fewiquick | E22: Fewiquick | F22: 0 | I22: =F22+G22-H22 -> 0 | J22: 55 | K22: =I22*J22 -> 0
A23: VN0023EQ10018 | B23: EQ10018 | C23: 18 | D23: BROWN TAPE 2" | E23: TAPE | I23: =F23+G23-H23 -> 0 | J23: 38 | K23: =I23*J23 -> 0
A24: VN0113EQ10019 | B24: EQ10019 | C24: 19 | D24: CIRCUIT LACQUER 400ML (6130005500) AMBERSIL | E24: CIRCUIT LACQUER | I24: =F24+G24-H24 -> 0 | J24: 450 | K24: =I24*J24 -> 0
A25: VN0113EQ10020 | B25: EQ10020 | C25: 20 | D25: TUBE LIGHT -4 FT COTTON BOX (126 X 430 X 430 ) | E25: Packing Box | I25: =F25+G25-H25 -> 0 | J25: 101 | K25: =I25*J25 -> 0
A26: VN0113EQ10021 | B26: EQ10021 | C26: 21 | D26: TUBE LIGHT -2 FT COTTON BOX (126 X 430 X 430 ) | E26: Packing Box | I26: =F26+G26-H26 -> 0 | J26: 69 | K26: =I26*J26 -> 0
A27: VN0113EQ10022 | B27: EQ10022 | C27: 22 | D27: T8-TUBE LIGHT -DRIVER COTTON BOX | E27: Packing Box | I27: =F27+G27-H27 -> 0 | J27: 21 | K27: =I27*J27 -> 0
A28: VN0113EQ10023 | B28: EQ10023 | C28: 24 | D28: 15 WATT DOWN LIGHT COTTON BOX | E28: Packing Box | I28: =F28+G28-H28 -> 0 | J28: 9 | K28: =I28*J28 -> 0
A29: VN0113EQ10024 | B29: EQ10024 | C29: 25 | D29: TUBE LIGHT BOX (L-40 X 1240X40 ) | E29: Packing Box | I29: =F29+G29-H29 -> 0 | J29: 6 | K29: =I29*J29 -> 0
A30: VN0045EQ10025 | B30: EQ10025 | C30: 26 | D30: TUBE LIGHT HEAT SINKABLE SLEEVE 10 MM | E30: Shinkable Sleeve | I30: =F30+G30-H30 -> 0 | J30: 9 | K30: =I30*J30 -> 0
B31: EQ10026 | C31: 27 | D31: BUBBLE COVER | E31: BUBBLE ROLLE | I31: =F31+G31-H31 -> 0 | J31: 1300 | K31: =I31*J31 -> 0
B32: EQ10027 | C32: 28 | D32: GLU STICK | E32: GLU STICK | F32: 0 | G32: 30 | H32: =5+5+3+3 -> 16 | I32: 35 | J32: 9 | K32: =I32*J32 -> 315
B33: EQ10028 | C33: 29 | D33: BALE PATTI | E33: BALE PATTI | I33: =F33+G33-H33 -> 0 | K33: =I33*J33 -> 0
B34: EQ10029 | C34: 30 | D34: OK STICKER | E34: STICKER | I34: =F34+G34-H34 -> 0 | K34: =I34*J34 -> 0
B35: EQ10030 | C35: 31 | D35: PVC INSULATION TAPE | E35: INSULATION TAPE | I35: =F35+G35-H35 -> 0 | J35: 10 | K35: =I35*J35 -> 0
B36: EQ10031 | C36: 31 | D36: Cello Tape 1" | E36: TAPE | K36: 0
B37: EQ10032 | C37: 32 | D37: HEAT SHRINKABE SLEEVE 16MM | E37: SLEEVE | F37: 100 | H37: 100 | I37: =F37+G37-H37 -> 0 | K37: =I37*J37 -> 0
B38: EQ10033 | C38: 38 | D38: HEAT SHRINKABE SLEEVE 18MM | E38: SHRINKABBLE SLEEVE | F38: 0 | G38: =100+100 -> 200 | H38: 200 | I38: =F38+G38-H38 -> 0 | J38: 16 | K38: =I38*J38 -> 0
B39: EQ10034 | C39: 34 | D39: BULB CAP | E39: BULB CAP | F39: 7 | I39: =F39+G39-H39 -> 7 | K39: =I39*J39 -> 0
B40: EQ10035 | C40: 35 | D40: TUBE LIGHT CLAMPS | E40: CLAMPS | F40: 230 | I40: =F40+G40-H40 -> 230 | K40: =I40*J40 -> 0
B41: EQ10036 | C41: 36 | D41: TUBE LIGHT DIFFUSER -PC SERAATION TYPE | E41: DIFFUSER | F41: 5 | G41: 50 | I41: =F41+G41-H41 -> 55 | J41: 35 | K41: =I41*J41 -> 1925
B42: EQ10037 | C42: 37 | D42: TUBE LIGHT DIFFUSER -PC CLEAR TYPE | E42: DIFFUSER | F42: 7 | G42: 0 | H42: 1 | I42: =F42+G42-H42 -> 6 | J42: 35 | K42: =I42*J42 -> 210
B43: EQ10038 | C43: 33 | D43: INTEGRATED END CAP TUBE LIGHT | E43: END CAP | F43: 49 | H43: =4+30+2+10+3 -> 49 | I43: =F43+G43-H43 -> 0 | K43: =I43*J43 -> 0
...

Sheet IC
A2: IC STORE STOCK
A4: RAWMATERIAL CODE | B4: CATAGARE NO | C4: SLNO | D4: PART NO | E4: DESCRIPTION | F4: PHY QTY | G4: RECEIPT | H4: ISSUE | I4: BALANCE | J4: UNIT PRICE | K4: AMOUNT
A5: SM0105IC15001 | B5: IC15001 | C5: 1 | D5: SM3300 | E5: IC | F5: =8220+200 -> 8420 | G5: 32000 | H5: =10+2+500+1000+250+702+100+50+1000+50+5+1+10 -> 3680 | I5: =F5+G5-H5 -> 36740 | J5: 15 | K5: =I5*J5 -> 551100 | L5: =+K5/$K$26 -> 0.7522158
A6: SM0105IC15002 | B6: IC15002 | C6: 2 | D6: SM8900 | E6: IC | F6: 1376 | I6: =F6+G6-H6 -> 1376 | J6: 15 | K6: =I6*J6 -> 20640 | L6: =+K6/$K$26 -> 0.028172263
A7: SM0105IC15003 | B7: IC15003 | C7: 3 | D7: CS8902 | E7: IC | F7: =1549+2500 -> 4049 | I7: =F7+G7-H7 -> 4049 | J7: 15 | K7: =I7*J7 -> 60735 | L7: =+K7/$K$26 -> 0.082899341
A8: VN0035IC15004 | B8: IC15004 | C8: 4 | D8: FAN7346MX SCR SGP | E8: IC | F8: 10 | I8: =F8+G8-H8 -> 10 | J8: 20 | K8: =I8*J8 -> 200 | L8: =+K8/$K$26 -> 0.00027298704
A9: VN0035IC15005 | B9: IC15005 | C9: 5 | D9: 23AB FO8H60S | E9: IC | F9: 19 | I9: =F9+G9-H9 -> 19 | J9: 15 | K9: =I9*J9 -> 285 | L9: =+K9/$K$26 -> 0.00038900654
A10: VN0035IC15006 | B10: IC15006 | C10: 6 | D10: FL7930BMX SCR SGP | E10: IC | F10: 10 | I10: =F10+G10-H10 -> 10 | J10: 10 | K10: =I10*J10 -> 100 | L10: =+K10/$K$26 -> 0.00013649352
A11: VN0035IC15007 | B11: IC15007 | C11: 7 | D11: B19AC FLS 1800XS | E11: IC | I11: =F11+G11-H11 -> 0 | J11: 15 | K11: =I11*J11 -> 0 | L11: =+K11/$K$26 -> 0
A12: VN0035IC15008 | B12: IC15008 | C12: 8 | D12: 1B46AC-FDPF12N60 NZ | E12: IC | I12: =F12+G12-H12 -> 0 | J12: 10 | K12: =I12*J12 -> 0 | L12: =+K12/$K$26 -> 0
A13: VN0035IC15009 | B13: IC15009 | C13: 9 | D13: 12F675 | E13: IC | I13: =F13+G13-H13 -> 0 | J13: 12 | K13: =I13*J13 -> 0 | L13: =+K13/$K$26 -> 0
A14: VN0035IC15010 | B14: IC15010 | C14: 10 | D14: SM6300A | E14: IC | F14: 99 | I14: =F14+G14-H14 -> 99 | J14: 20 | K14: =I14*J14 -> 1980 | L14: =+K14/$K$26 -> 0.0027025717
A15: VN0035IC15011 | B15: IC15011 | C15: 11 | D15: SMD ICSSW2802 SOT23-6 | E15: IC | F15: 500 | I15: =F15+G15-H15 -> 500 | J15: 20 | K15: =I15*J15 -> 10000 | L15: =+K15/$K$26 -> 0.013649352
A16: VN0035IC15012 | B16: IC15012 | C16: 12 | D16: SKW1126 | E16: IC | I16: =F16+G16-H16 -> 0 | J16: 20 | K16: =I16*J16 -> 0 | L16: =+K16/$K$26 -> 0
A17: VN0035IC15013 | B17: IC15013 | C17: 13 | D17: SSW2601A | E17: IC | I17: =F17+G17-H17 -> 0 | J17: 20 | K17: =I17*J17 -> 0 | L17: =+K17/$K$26 -> 0
A18: VN0035IC15014 | B18: IC15014 | C18: 14 | D18: Printing Mark | E18: IC | I18: =F18+G18-H18 -> 0 | J18: 20 | K18: =I18*J18 -> 0 | L18: =+K18/$K$26 -> 0
A19: SM0105IC15015 | B19: IC15015 | C19: 15 | D19: SM6300B | E19: IC | F19: =3000+3000+317+130 -> 6447 | H19: =10+400+20+5+1+8+2000+1+1000 -> 3445 | I19: =F19+G19-H19 -> 3002 | J19: 20 | K19: =I19*J19 -> 60040 | L19: =+K19/$K$26 -> 0.081950711
B20: IC15016 | C20: 16 | D20: SM2601A | E20: IC | F20: 970 | H20: =50+100+6 -> 156 | I20: =F20+G20-H20 -> 814 | J20: 18 | K20: =I20*J20 -> 14652 | L20: =+K20/$K$26 -> 0.019999031
B21: IC15017 | C21: 17 | D21: SMA6301 | E21: IC | F21: 600 | I21: =F21+G21-H21 -> 600 | J21: 20 | K21: =I21*J21 -> 12000 | L21: =+K21/$K$26 -> 0.016379223
B22: IC15018 | C22: 18 | D22: IE817 | E22: IC | F22: =70+75+40 -> 185 | I22: =F22+G22-H22 -> 185 | J22: 2.5 | K22: =I22*J22 -> 462.5 | L22: =+K22/$K$26 -> 0.00063128254
B23: IC15019 | C23: 19 | D23: IC BASE 28 PIN 2.54MM | E23: IC BASE | F23: 63 | I23: =F23+G23-H23 -> 63 | J23: 7 | K23: =I23*J23 -> 441 | L23: =+K23/$K$26 -> 0.00060193643
B24: IC15020 | C24: 20 | D24: SM UA 2121 JC | E24: IC | F24: 100 | I24: =F24+G24-H24 -> 100 | J24: 8 | K24: =I24*J24 -> 800 | L24: =+K24/$K$26 -> 0.0010919482
B25: IC15021 | C25: 21 | D25: AT 7373 | E25: IC | F25: 20 | I25: =F25+G25-H25 -> 20 | J25: 9 | K25: =I25*J25 -> 180 | L25: =+K25/$K$26 -> 0.00024568834
J26: TOTAL | K26: =SUM(K5:K23) -> 732635.5

Sheet ENCLOSURES
A1: ENCLOSURE STORE STOCK
A3: RAWMATERIAL CODE | B3: CATAGARE NO | C3: SLNO | D3: PART NO | E3: DESCRIPTION | F3: PHY QTY | G3: UNIT PRICE | H3: AMOUNT
A4: VN0004ES07001 | B4: ES07001 | C4: 1 | D4: Down Light 3 Watt Enclosure | E4: ENCLOSURE | F4: 0 | G4: 37.4 | H4: =G4*F4 -> 0
A5: VN0004ES07002 | B5: ES07002 | C5: 2 | D5: Down Light 5 Watt Enclosure | E5: ENCLOSURE | F5: 0 | G5: 49.5 | H5: =G5*F5 -> 0
A6: VN0004ES07003 | B6: ES07003 | C6: 3 | D6: Down Light 9 Watt Enclosure | E6: ENCLOSURE | F6: 0 | G6: 55 | H6: =G6*F6 -> 0
A7: VN0004ES07004 | B7: ES07004 | C7: 4 | D7: Down Light 15 Watt Enclosure | E7: ENCLOSURE | F7: 0 | G7: 60.5 | H7: =G7*F7 -> 0
A8: VN0007ES07005 | B8: ES07005 | C8: 5 | D8: T8-TUBE LIGHT FIXTURE | E8: ENCLOSURE | F8: 0 | G8: 120 | H8: =G8*F8 -> 0
A9: VN0004ES07006 | B9: ES07006 | C9: 6 | D9: 1 X 1 DLS | E9: ENCLOSURE | F9: 2 | G9: 420 | H9: =G9*F9 -> 840
A10: VN0004ES07007 | B10: ES07007 | C10: 7 | D10: MAK DLP 1080 5W DOWN LIGHT ECO PLUS FITTINGS | E10: ENCLOSURE | F10: 0 | G10: 175 | H10: =G10*F10 -> 0
A11: VN0004ES07008 | B11: ES07008 | C11: 8 | D11: 1/2 FEET DLS | E11: ENCLOSURE | F11: 1 | G11: 150 | H11: =G11*F11 -> 150
A12: VN0004ES07009 | B12: ES07009 | C12: 9 | D12: T8 TUBE LIGHT LOADS | E12: ENCLOSURE | F12: 0 | G12: 750 | H12: =G12*F12 -> 0
A13: VN0004ES07010 | B13: ES07010 | C13: 10 | D13: BULP WHITE ENCLOSURE 3WATT | E13: ENCLOSURE | F13: 20 | G13: 77 | H13: =G13*F13 -> 1540
A14: VN0004ES07011 | B14: ES07011 | C14: 11 | D14: BULP WHITE ENCLOSURE 7WATT | E14: ENCLOSURE | F14: 92 | G14: 95 | H14: =G14*F14 -> 8740
A15: VN0004ES07012 | B15: ES07012 | C15: 12 | D15: BULP SILVER ENCLOSURE 10WATT | E15: ENCLOSURE | F15: 10 | G15: 105 | H15: =G15*F15 -> 1050
... A29: VN0007ES07026 | B29: ES07026 | C29: 26 | D29: LED CEILING LIGHT HOUSING+SMD3528 9W,PCBA | E29: ENCLOSURE | F29: 0 | G29: 181.5 | H29: =G29*F29 -> 0
B30: ES07027 | C30: 27 | D30: channel T8 4 Feet Regular | E30: ENCLOSURE | F30: 20 | G30: 40 | H30: =G30*F30 -> 800
B31: ES07028 | C31: 28 | D31: RGB LED UNDER WATER LIGHT | E31: ENCLOSURE | F31: 0 | G31: 0 | H31: =G31*F31 -> 0
B32: ES07029 | C32: 29 | D32: LED CEILING LIGHT HOUSING+SMD5730 (MW) | E32: ENCLOSURE | F32: 0 | G32: 236.5 | H32: =G32*F32 -> 0
B33: ES07030 | C33: 30 | D33: T8 TUBE LIGHT PATTI 12 X 40 | E33: ENCLOSURE | F33: 0 | G33: 0 | H33: =G33*F33 -> 0
B34: ES07031 | C34: 31 | D34: HB-04 | E34: ENCLOSURE | F34: 0 | G34: 0 | H34: =G34*F34 -> 0
