Workbook

Sheet TL 5.4 VER
A1: Product Code | C1: DR13021 | L1: Kitting Quantity | N1: ='Detail-Planner'!E5 -> 0
A3: Bill Of Materials - 80V 220mA (18~22W Compatible)TUBE LIGHT 5.4 VER
A5: Item | B5: Raw Material Code | C5: Quantity | D5: Reference | E5: Part | F5: Package | G5: Tolerence | H5: Make | I5: Vendor | J5: Unit Cost | K5: Total | L5: STOCK | M5: Interim Value | N5: Kitting Quantity | O5: PRICE | P5: SUPPLIER NAME | Q5: PAYMENT TERMS
A6: 1 | B6: DE05001 | C6: 1 | D6: BD1 | E6: B10S-G(1000V 1A) | F6: TO-269AA | H6: GOODARC,MIC,HY | I6: HICOTRONICS,MIC,SAINI | J6: 2.6 | K6: =Table13[[#This Row],[Quantity]]*Table13[[#This Row],[Unit Cost]] -> 2.6 | L6: 5980 | M6: =Table13[[#This Row],[Quantity]]*AA6-Table13[[#This Row],[STOCK]] -> -5980 | N6: =IF(Table13[[#This Row],[Interim Value]]<0,0,Table13[[#This Row],[Interim Value]]) -> 0 | O6: =Table13[[#This Row],[Kitting Quantity]]*Table13[[#This Row],[Unit Cost]] -> 0 | P6: HICOTRONICS | Q6: 60DAYS CREDIT | AA6: =N1 -> 0
A7: 2 | B7: CP04007 | C7: 1 | D7: C1 | E7: 103/1KVA | F7: CAP_DISC_200 | G7: 10% | H7: HEL / JACKCON/GUJARAT POLY AVX | I7: SAINI,HICOTRONICS,GUJARAT POLY AVX | J7: 0.6 | K7: =Table13[[#This Row],[Quantity]]*Table13[[#This Row],[Unit Cost]] -> 0.6 | L7: 30000 | M7: =Table13[[#This Row],[Quantity]]*AA7-Table13[[#This Row],[STOCK]] -> -30000 | N7: =IF(Table13[[#This Row],[Interim Value]]<0,0,Table13[[#This Row],[Interim Value]]) -> 0 | O7: =Table13[[#This Row],[Kitting Quantity]]*Table13[[#This Row],[Unit Cost]] -> 0 | P7: SUN MICRO COMPONENTS | Q7: 60DAYS CREDIT | AA7: =N1 -> 0
A8: 3 | B8: RS01047 | C8: 1 | D8: C3 | E8: 100P/50V | F8: C0805 | G8: 5% | H8: YAGEO,AVX,KEMET | I8: SAINI,HICOTRONICS,GUJARAT POLY AVX | J8: 0.2 | K8: =Table13[[#This Row],[Quantity]]*Table13[[#This Row],[Unit Cost]] -> 0.2 | L8: 16000 | M8: =Table13[[#This Row],[Quantity]]*AA8-Table13[[#This Row],[STOCK]] -> -16000 | N8: =IF(Table13[[#This Row],[Interim Value]]<0,0,Table13[[#This Row],[Interim Value]]) -> 0 | O8: =Table13[[#This Row],[Kitting Quantity]]*Table13[[#This Row],[Unit Cost]] -> 0 | P8: HICOTRONICS | Q8: 60DAYS CREDIT | AA8: =N1 -> 0
A9: 4 | B9: RS01006 | C9: 1 | D9: C4 | E9: 1uF/50V | F9: C0805 | G9: 5% | H9: YAGEO,AVX,KEMET | I9: SAINI,HICOTRONICS,GUJARAT POLY AVX | J9: 0.35 | K9: =Table13[[#This Row],[Quantity]]*Table13[[#This Row],[Unit Cost]] -> 0.35 | L9: 18000 | M9: =Table13[[#This Row],[Quantity]]*AA9-Table13[[#This Row],[STOCK]] -> -18000 | N9: =IF(Table13[[#This Row],[Interim Value]]<0,0,Table13[[#This Row],[Interim Value]]) -> 0 | O9: =Table13[[#This Row],[Kitting Quantity]]*Table13[[#This Row],[Unit Cost]] -> 0 | P9: HICOTRONICS | Q9: 60DAYS CREDIT | AA9: =N1 -> 0
A10: 5 | B10: RS01091 | C10: 1 | D10: C5 | E10: 100nF/50V | F10: C0805 | G10: 5% | H10: YAGEO,AVX,KEMET | I10: SAINI,HICOTRONICS,GUJARAT POLY AVX | J10: 0.2 | K10: =Table13[[#This Row],[Quantity]]*Table13[[#This Row],[Unit Cost]] -> 0.2 | L10: 16000 | M10: =Table13[[#This Row],[Quantity]]*AA10-Table13[[#This Row],[STOCK]] -> -16000 | N10: =IF(Table13[[#This Row],[Interim Value]]<0,0,Table13[[#This Row],[Interim Value]]) -> 0 | O10: =Table13[[#This Row],[Kitting Quantity]]*Table13[[#This Row],[Unit Cost]] -> 0 | P10: HICOTRONICS | Q10: 60DAYS CREDIT | AA10: =N1 -> 0
A11: 6 | B11: CP04007 | C11: 1 | D11: C6 | E11: 103, 1KVA | F11: CAP_DISC_200 | G11: 10% | H11: HEL / JACKCON/GUJARAT POLY AVX | I11: SAINI,HICOTRONICS,GUJARAT POLY AVX | J11: 0.6 | K11: =Table13[[#This Row],[Quantity]]*Table13[[#This Row],[Unit Cost]] -> 0.6 | L11: 0 | M11: =Table13[[#This Row],[Quantity]]*AA11-Table13[[#This Row],[STOCK]] -> 0 | N11: =IF(Table13[[#This Row],[Interim Value]]<0,0,Table13[[#This Row],[Interim Value]]) -> 0 | O11: =Table13[[#This Row],[Kitting Quantity]]*Table13[[#This Row],[Unit Cost]] -> 0 | P11: SUN MICRO COMPONENTS | Q11: 60DAYS CREDIT | AA11: =N1 -> 0
A12: 7 | B12: CP04007 | C12: 1 | D12: C7 | E12: 103/1KVA | F12: CAP_DISC_200 | G12: 10% | H12: HEL / JACKCON/GUJARAT POLY AVX | I12: SAINI,HICOTRONICS,GUJARAT POLY AVX | J12: 0.6 | K12: =Table13[[#This Row],[Quantity]]*Table13[[#This Row],[Unit Cost]] -> 0.6 | L12: 0 | M12: =Table13[[#This Row],[Quantity]]*AA12-Table13[[#This Row],[STOCK]] -> 0 | N12: =IF(Table13[[#This Row],[Interim Value]]<0,0,Table13[[#This Row],[Interim Value]]) -> 0 | O12: =Table13[[#This Row],[Kitting Quantity]]*Table13[[#This Row],[Unit Cost]] -> 0 | P12: SUN MICRO COMPONENTS | Q12: 60DAYS CREDIT | AA12: =N1 -> 0
A13: 8 | B13: CP04004 | C13: 1 | D13: C8 | E13: P2G102K(275VAC) | F13: PEIR MYLAR CAP | G13: 10% | H13: PIA | I13: SREE ELECTRONICS,TEXTONIC | J13: 0.8 | K13: =Table13[[#This Row],[Quantity]]*Table13[[#This Row],[Unit Cost]] -> 0.8 | L13: 700 | M13: =Table13[[#This Row],[Quantity]]*AA13-Table13[[#This Row],[STOCK]] -> -700 | N13: =IF(Table13[[#This Row],[Interim Value]]<0,0,Table13[[#This Row],[Interim Value]]) -> 0 | O13: =Table13[[#This Row],[Kitting Quantity]]*Table13[[#This Row],[Unit Cost]] -> 0 | P13: SHREE ELECTRONICS | Q13: 60DAYS PDC | AA13: =N1 -> 0
A14: 9 | B14: CP04022 | C14: 2 | D14: CP1,CP2 | E14: 22uF/250V(105) | F14: (10mm*17mm) | G14: 10% | H14: JACKCON,SAMHWA | I14: SAINI ,TEXONICS | J14: 3.6 | K14: =Table13[[#This Row],[Quantity]]*Table13[[#This Row],[Unit Cost]] -> 7.2 | L14: 300 | M14: =Table13[[#This Row],[Quantity]]*AA14-Table13[[#This Row],[STOCK]] -> -300 | N14: =IF(Table13[[#This Row],[Interim Value]]<0,0,Table13[[#This Row],[Interim Value]]) -> 0 | O14: =Table13[[#This Row],[Kitting Quantity]]*Table13[[#This Row],[Unit Cost]] -> 0 | P14: SUN MICRO COMPONENTS | Q14: 60DAYS CREDIT | AA14: =N1 -> 0
A15: 10 | B15: DE05013 | C15: 1 | D15: D1 | E15: MUR460 | F15: DO-201AD | H15: GOODARC,MIC,HY | I15: SAINI,HICOTRONICS,GUJARAT POLY AVX | J15: 3.5 | K15: =Table13[[#This Row],[Quantity]]*Table13[[#This Row],[Unit Cost]] -> 3.5 | L15: 8400 | M15: =Table13[[#This Row],[Quantity]]*AA15-Table13[[#This Row],[STOCK]] -> -8400 | N15: =IF(Table13[[#This Row],[Interim Value]]<0,0,Table13[[#This Row],[Interim Value]]) -> 0 | O15: =Table13[[#This Row],[Kitting Quantity]]*Table13[[#This Row],[Unit Cost]] -> 0 | P15: HICOTRONICS | Q15: 60DAYS CREDIT | AA15: =N1 -> 0
A16: 11 | B16: DE05006 | C16: 3 | D16: D2,D3,D4 | E16: SS4007(1000V 1A) | F16: SMA | H16: GOODARC,MIC,HY | I16: SAINI,HICOTRONICS,GUJARAT POLY AVX | J16: 0.45 | K16: =Table13[[#This Row],[Quantity]]*Table13[[#This Row],[Unit Cost]] -> 1.35 | L16: 0 | M16: =Table13[[#This Row],[Quantity]]*AA16-Table13[[#This Row],[STOCK]] -> 0 | N16: =IF(Table13[[#This Row],[Interim Value]]<0,0,Table13[[#This Row],[Interim Value]]) -> 0 | O16: =Table13[[#This Row],[Kitting Quantity]]*Table13[[#This Row],[Unit Cost]] -> 0 | P16: HICOTRONICS | Q16: 60DAYS CREDIT | AA16: =N1 -> 0
A17: 12 | B17: DE05015 | C17: 1 | D17: F1 | E17: 1A, 250V(SLOW BLOW) | F17: (3.6mm*10mm) | H17: UCHI/PROTECTRON | I17: SAINI,PUNITH ELECTRONICS | J17: 2.5 | K17: =Table13[[#This Row],[Quantity]]*Table13[[#This Row],[Unit Cost]] -> 2.5 | L17: 2500 | M17: =Table13[[#This Row],[Quantity]]*AA17-Table13[[#This Row],[STOCK]] -> -2500 | N17: =IF(Table13[[#This Row],[Interim Value]]<0,0,Table13[[#This Row],[Interim Value]]) -> 0 | O17: =Table13[[#This Row],[Kitting Quantity]]*Table13[[#This Row],[Unit Cost]] -> 0 | P17: SUN MICRO COMPONENTS | Q17: 60DAYS CREDIT | AA17: =N1 -> 0
A18: 13 | B18: IN08003 | C18: 1 | D18: L4 | E18: 3mH (700mA)MTX3MH | F18: EE16 VERTICAL | G18: 5% | H18: METRONIX | I18: METRONIX | J18: 7.5 | K18: =Table13[[#This Row],[Quantity]]*Table13[[#This Row],[Unit Cost]] -> 7.5 | L18: 0 | M18: =Table13[[#This Row],[Quantity]]*AA18-Table13[[#This Row],[STOCK]] -> 0 | N18: =IF(Table13[[#This Row],[Interim Value]]<0,0,Table13[[#This Row],[Interim Value]]) -> 0 | O18: =Table13[[#This Row],[Kitting Quantity]]*Table13[[#This Row],[Unit Cost]] -> 0 | P18: METRONIX | Q18: 90 DAYS CREDIT | AA18: =N1 -> 0
A19: 14 | B19: MOV11005 | C19: 1 | D19: MOV1 | E19: 10D471K | F19: 10mm | H19: EPCOS/UCHI/HEL | I19: HICOTRONICS,SAINI | J19: 3 | K19: =Table13[[#This Row],[Quantity]]*Table13[[#This Row],[Unit Cost]] -> 3 | L19: 4400 | M19: =Table13[[#This Row],[Quantity]]*AA19-Table13[[#This Row],[STOCK]] -> -4400 | N19: =IF(Table13[[#This Row],[Interim Value]]<0,0,Table13[[#This Row],[Interim Value]]) -> 0 | O19: =Table13[[#This Row],[Kitting Quantity]]*Table13[[#This Row],[Unit Cost]] -> 0 | P19: SUN MICRO COMPONENTS | Q19: 60DAYS CREDIT | AA19: =N1 -> 0
A20: 15 | B20: DE05014 | C20: 1 | D20: POT1 | E20: 10K | F20: TRIMMER | G20: 5% | I20: SREE ELECTRONICS,TEXTONIC | J20: 1.6 | K20: =Table13[[#This Row],[Quantity]]*Table13[[#This Row],[Unit Cost]] -> 1.6 | L20: 200 | M20: =Table13[[#This Row],[Quantity]]*AA20-Table13[[#This Row],[STOCK]] -> -200 | N20: =IF(Table13[[#This Row],[Interim Value]]<0,0,Table13[[#This Row],[Interim Value]]) -> 0 | O20: =Table13[[#This Row],[Kitting Quantity]]*Table13[[#This Row],[Unit Cost]] -> 0 | P20: SHREE ELECTRONICS | Q20: 60DAYS PDC | AA20: =N1 -> 0
A21: 16 | B21: MF02004 | C21: 1 | D21: Q1 | E21: H4N60 | F21: TO-220 METAL | H21: FAIRCHILD ,HY ,SEM | I21: SAINI,SEM | J21: 11.9 | K21: =Table13[[#This Row],[Quantity]]*Table13[[#This Row],[Unit Cost]] -> 11.9 | L21: 2213 | M21: =Table13[[#This Row],[Quantity]]*AA21-Table13[[#This Row],[STOCK]] -> -2213 | N21: =IF(Table13[[#This Row],[Interim Value]]<0,0,Table13[[#This Row],[Interim Value]]) -> 0 | O21: =Table13[[#This Row],[Kitting Quantity]]*Table13[[#This Row],[Unit Cost]] -> 0 | P21: SUN MICRO COMPONENTS | Q21: 60DAYS CREDIT | AA21: =N1 -> 0
A22: 17 | B22: RS01009 | C22: 1 | D22: R1 | E22: 0R | F22: R0805 | G22: 1% | H22: YAGEO,ROYALOHM ,UNIOHAM | I22: HICOTRONICS,GUJARAT POLY AVX,ELECTRONICA | J22: 0.05 | K22: =Table13[[#This Row],[Quantity]]*Table13[[#This Row],[Unit Cost]] -> 0.05 | L22: 15000 | M22: =Table13[[#This Row],[Quantity]]*AA22-Table13[[#This Row],[STOCK]] -> -15000 | N22: =IF(Table13[[#This Row],[Interim Value]]<0,0,Table13[[#This Row],[Interim Value]]) -> 0 | O22: =Table13[[#This Row],[Kitting Quantity]]*Table13[[#This Row],[Unit Cost]] -> 0 | P22: HICOTRONICS | Q22: 60DAYS CREDIT | AA22: =N1 -> 0
A23: 18 | B23: RS01010 | C23: 1 | D23: R2 | E23: 0.68E | F23: R1206 | G23: 1% | H23: YAGEO,ROYALOHM ,UNIOHAM | I23: HICOTRONICS,GUJARAT POLY AVX,ELECTRONICA | J23: 0.5 | K23: =Table13[[#This Row],[Quantity]]*Table13[[#This Row],[Unit Cost]] -> 0.5 | L23: 10000 | M23: =Table13[[#This Row],[Quantity]]*AA23-Table13[[#This Row],[STOCK]] -> -10000 | N23: =IF(Table13[[#This Row],[Interim Value]]<0,0,Table13[[#This Row],[Interim Value]]) -> 0 | O23: =Table13[[#This Row],[Kitting Quantity]]*Table13[[#This Row],[Unit Cost]] -> 0 | P23: HICOTRONICS | Q23: 60DAYS CREDIT | AA23: =N1 -> 0
A24: 19 | B24: RS01096 | C24: 1 | D24: R3 | E24: 0.68E | F24: R1206 | G24: 1% | H24: YAGEO,ROYALOHM ,UNIOHAM | I24: HICOTRONICS,GUJARAT POLY AVX,ELECTRONICA | J24: 0.5 | K24: =Table13[[#This Row],[Quantity]]*Table13[[#This Row],[Unit Cost]] -> 0.5 | L24: 0 | M24: =Table13[[#This Row],[Quantity]]*AA24-Table13[[#This Row],[STOCK]] -> 0 | N24: =IF(Table13[[#This Row],[Interim Value]]<0,0,Table13[[#This Row],[Interim Value]]) -> 0 | O24: =Table13[[#This Row],[Kitting Quantity]]*Table13[[#This Row],[Unit Cost]] -> 0 | P24: HICOTRONICS | Q24: 60DAYS CREDIT | AA24: =N1 -> 0
A25: 20 | B25: RS01092 | C25: 1 | D25: R4 | E25: 49.9K | F25: R0603 | G25: 5% | H25: YAGEO,ROYALOHM ,UNIOHAM | I25: HICOTRONICS,GUJARAT POLY AVX,ELECTRONICA | J25: 0.05 | K25: =Table13[[#This Row],[Quantity]]*Table13[[#This Row],[Unit Cost]] -> 0.05 | L25: 15000 | M25: =Table13[[#This Row],[Quantity]]*AA25-Table13[[#This Row],[STOCK]] -> -15000 | N25: =IF(Table13[[#This Row],[Interim Value]]<0,0,Table13[[#This Row],[Interim Value]]) -> 0 | O25: =Table13[[#This Row],[Kitting Quantity]]*Table13[[#This Row],[Unit Cost]] -> 0 | P25: HICOTRONICS | Q25: 60DAYS CREDIT | AA25: =N1 -> 0
A26: 21 | C26: 1 | D26: R5 | E26: NC | F26: R0603 | J26: 0 | K26: =Table13[[#This Row],[Quantity]]*Table13[[#This Row],[Unit Cost]] -> 0 | L26: 0 | M26: =Table13[[#This Row],[Quantity]]*AA26-Table13[[#This Row],[STOCK]] -> 0 | N26: =IF(Table13[[#This Row],[Interim Value]]<0,0,Table13[[#This Row],[Interim Value]]) -> 0 | O26: =Table13[[#This Row],[Kitting Quantity]]*Table13[[#This Row],[Unit Cost]] -> 0 | P26: HICOTRONICS | Q26: 60DAYS CREDIT | AA26: =N1 -> 0
A27: 22 | B27: RS01007 | C27: 1 | D27: R6 | E27: 100K | F27: R0603 | G27: 1% | H27: YAGEO,ROYALOHM ,UNIOHAM | I27: HICOTRONICS,GUJARAT POLY AVX,ELECTRONICA | J27: 0.05 | K27: =Table13[[#This Row],[Quantity]]*Table13[[#This Row],[Unit Cost]] -> 0.05 | L27: 10000 | M27: =Table13[[#This Row],[Quantity]]*AA27-Table13[[#This Row],[STOCK]] -> -10000 | N27: =IF(Table13[[#This Row],[Interim Value]]<0,0,Table13[[#This Row],[Interim Value]]) -> 0 | O27: =Table13[[#This Row],[Kitting Quantity]]*Table13[[#This Row],[Unit Cost]] -> 0 | P27: HICOTRONICS | Q27: 60DAYS CREDIT | AA27: =N1 -> 0
A28: 23 | B28: RS01093 | C28: 1 | D28: R7 | E28: 680K | F28: R0603 | G28: 1% | H28: YAGEO,ROYALOHM ,UNIOHAM | I28: HICOTRONICS,GUJARAT POLY AVX,ELECTRONICA | J28: 0.05 | K28: =Table13[[#This Row],[Quantity]]*Table13[[#This Row],[Unit Cost]] -> 0.05 | L28: 10000 | M28: =Table13[[#This Row],[Quantity]]*AA28-Table13[[#This Row],[STOCK]] -> -10000 | N28: =IF(Table13[[#This Row],[Interim Value]]<0,0,Table13[[#This Row],[Interim Value]]) -> 0 | O28: =Table13[[#This Row],[Kitting Quantity]]*Table13[[#This Row],[Unit Cost]] -> 0 | P28: HICOTRONICS | Q28: 60DAYS CREDIT | AA28: =N1 -> 0
A29: 24 | B29: RS01005 | C29: 1 | D29: R8 | E29: 10E | F29: R0603 | G29: 1% | H29: YAGEO,ROYALOHM ,UNIOHAM | I29: HICOTRONICS,GUJARAT POLY AVX,ELECTRONICA | J29: 0.05 | K29: =Table13[[#This Row],[Quantity]]*Table13[[#This Row],[Unit Cost]] -> 0.05 | L29: 10000 | M29: =Table13[[#This Row],[Quantity]]*AA29-Table13[[#This Row],[STOCK]] -> -10000 | N29: =IF(Table13[[#This Row],[Interim Value]]<0,0,Table13[[#This Row],[Interim Value]]) -> 0 | O29: =Table13[[#This Row],[Kitting Quantity]]*Table13[[#This Row],[Unit Cost]] -> 0 | P29: HICOTRONICS | Q29: 60DAYS CREDIT | AA29: =N1 -> 0
A30: 25 | B30: RS01094 | C30: 1 | D30: R10 | E30: 174KE | F30: R0603 | G30: 5% | H30: YAGEO,ROYALOHM ,UNIOHAM | I30: HICOTRONICS,GUJARAT POLY AVX,ELECTRONICA | J30: 0.05 | K30: =Table13[[#This Row],[Quantity]]*Table13[[#This Row],[Unit Cost]] -> 0.05 | L30: 10000 | M30: =Table13[[#This Row],[Quantity]]*AA30-Table13[[#This Row],[STOCK]] -> -10000 | N30: =IF(Table13[[#This Row],[Interim Value]]<0,0,Table13[[#This Row],[Interim Value]]) -> 0 | O30: =Table13[[#This Row],[Kitting Quantity]]*Table13[[#This Row],[Unit Cost]] -> 0 | P30: HICOTRONICS | Q30: 60DAYS CREDIT | AA30: =N1 -> 0
A31: 26 | B31: RS01095 | C31: 1 | D31: R11 | E31: 1K | F31: R0603 | G31: 5% | H31: YAGEO,ROYALOHM ,UNIOHAM | I31: HICOTRONICS,GUJARAT POLY AVX,ELECTRONICA | J31: 0.05 | K31: =Table13[[#This Row],[Quantity]]*Table13[[#This Row],[Unit Cost]] -> 0.05 | L31: 10000 | M31: =Table13[[#This Row],[Quantity]]*AA31-Table13[[#This Row],[STOCK]] -> -10000 | N31: =IF(Table13[[#This Row],[Interim Value]]<0,0,Table13[[#This Row],[Interim Value]]) -> 0 | O31: =Table13[[#This Row],[Kitting Quantity]]*Table13[[#This Row],[Unit Cost]] -> 0 | P31: HICOTRONICS | Q31: 60DAYS CREDIT | AA31: =N1 -> 0
A32: 27 | B32: RS01046 | C32: 1 | D32: R12 | E32: 430E | F32: R0603 | G32: 1% | H32: YAGEO,ROYALOHM ,UNIOHAM | I32: HICOTRONICS,GUJARAT POLY AVX,ELECTRONICA | J32: 0.05 | K32: =Table13[[#This Row],[Quantity]]*Table13[[#This Row],[Unit Cost]] -> 0.05 | L32: 10000 | M32: =Table13[[#This Row],[Quantity]]*AA32-Table13[[#This Row],[STOCK]] -> -10000 | N32: =IF(Table13[[#This Row],[Interim Value]]<0,0,Table13[[#This Row],[Interim Value]]) -> 0 | O32: =Table13[[#This Row],[Kitting Quantity]]*Table13[[#This Row],[Unit Cost]] -> 0 | P32: HICOTRONICS | Q32: 60DAYS CREDIT | AA32: =N1 -> 0
A33: 28 | C33: 1 | D33: R13 | E33: SHORT | F33: R1206 | H33: YAGEO,ROYALOHM ,UNIOHAM | J33: 0 | K33: =Table13[[#This Row],[Quantity]]*Table13[[#This Row],[Unit Cost]] -> 0 | L33: 0 | M33: =Table13[[#This Row],[Quantity]]*AA33-Table13[[#This Row],[STOCK]] -> 0 | N33: =IF(Table13[[#This Row],[Interim Value]]<0,0,Table13[[#This Row],[Interim Value]]) -> 0 | O33: =Table13[[#This Row],[Kitting Quantity]]*Table13[[#This Row],[Unit Cost]] -> 0 | AA33: =N1 -> 0
A34: 29 | B34: IC15001 | C34: 1 | D34: U1 | E34: SM3300 | F34: SO8 | H34: SEMTRONICS | I34: SEM | J34: 15 | K34: =Table13[[#This Row],[Quantity]]*Table13[[#This Row],[Unit Cost]] -> 15 | L34: 19494 | M34: =Table13[[#This Row],[Quantity]]*AA34-Table13[[#This Row],[STOCK]] -> -19494 | N34: =IF(Table13[[#This Row],[Interim Value]]<0,0,Table13[[#This Row],[Interim Value]]) -> 0 | O34: =Table13[[#This Row],[Kitting Quantity]]*Table13[[#This Row],[Unit Cost]] -> 0 | P34: SEM | AA34: =N1 -> 0
A35: 30 | B35: PCB09036 | C35: 1 | E35: PCB VER 5.4 | F35: (17mm*150mm) | I35: UNIVERSAL | J35: 15.7 | K35: =Table13[[#This Row],[Quantity]]*Table13[[#This Row],[Unit Cost]] -> 15.7 | L35: 1026 | M35: =Table13[[#This Row],[Quantity]]*AA35-Table13[[#This Row],[STOCK]] -> -1026 | N35: =IF(Table13[[#This Row],[Interim Value]]<0,0,Table13[[#This Row],[Interim Value]]) -> 0 | O35: =Table13[[#This Row],[Kitting Quantity]]*Table13[[#This Row],[Unit Cost]] -> 0 | P35: UNIVERSAL CIRCUTS | Q35: 60 DAYS | AA35: =N1 -> 0
A36: 31 | C36: 1 | E36: EMS COST | H36: EMADS | J36: 9 | K36: =Table13[[#This Row],[Quantity]]*Table13[[#This Row],[Unit Cost]] -> 9 | L36: 0 | M36: =Table13[[#This Row],[Quantity]]*AA36-Table13[[#This Row],[STOCK]] -> 0 | N36: =IF(Table13[[#This Row],[Interim Value]]<0,0,Table13[[#This Row],[Interim Value]]) -> 0 | O36: =Table13[[#This Row],[Kitting Quantity]]*Table13[[#This Row],[Unit Cost]] -> 0 | P36: FLIP CHIP | AA36: =N1 -> 0
A37: 32 | B37: EQ10069 | C37: 1 | E37: BAR CODE STICKER | J37: 0.3 | K37: =Table13[[#This Row],[Quantity]]*Table13[[#This Row],[Unit Cost]] -> 0.3 | L37: 0 | M37: =Table13[[#This Row],[Quantity]]*AA37-Table13[[#This Row],[STOCK]] -> 0 | N37: =IF(Table13[[#This Row],[Interim Value]]<0,0,Table13[[#This Row],[Interim Value]]) -> 0 | O37: =Table13[[#This Row],[Kitting Quantity]]*Table13[[#This Row],[Unit Cost]] -> 0 | AA37: =N1 -> 0
E38: TOTAL COST | K38: =SUBTOTAL(109,[Total]) -> 85.9 | AA38: =N1 -> 0
A39: Total Electronics Cost | O39: =SUM(Table13[PRICE]) -> 0
B42: BOM Value Split | F42: Kitting Value Split
B43: T/T | C43: =K34 -> 15 | F43: T/T | G43: =O34 -> 0
B44: 7 Days | F44: 7 Days | G44: 0
...

Sheet TL 5.8 VER
A1: Product Code | C1: DR13060 | K1: Kitting Quantity | N1: ='Detail-Planner'!E6 -> 0
A3: Product Description - TUBE LIGHT 5.8 VER
A5: Item | B5: Raw Material Code | C5: Quantity | D5: Reference | E5: Part | F5: Package | G5: Tolerence | H5: Make | I5: Vendor | J5: Unit Cost | K5: TOTAL | L5: STOCK | M5: Interim Value | N5: Kitting Quantity | O5: PRICE | P5: SUPPLIER NAME | Q5: PAYMENT TERMS
A6: 1 | B6: DE05001 | C6: 1 | D6: BD1 | E6: B10S | F6: MD6S_4P | G6: 10% | H6: GOODARC,MIC,HY | I6: HICOTRONICS,MIC,SAINI | J6: 2.6 | K6: =Table1479101156[[#This Row],[Unit Cost]]*Table1479101156[[#This Row],[Quantity]] -> 2.6 | L6: 0 | M6: =Table1479101156[[#This Row],[Quantity]]*Z6-Table1479101156[[#This Row],[STOCK]] -> 0 | N6: =IF(Table1479101156[[#This Row],[Interim Value]]<0,0,Table1479101156[[#This Row],[Interim Value]]) -> 0 | O6: =Table1479101156[[#This Row],[Kitting Quantity]]*Table1479101156[[#This Row],[Unit Cost]] -> 0 | P6: HICOTRONICS | Q6: 60DAYS CREDIT | Z6: =N1 -> 0
A7: 2 | B7: CP04007 | C7: 1 | D7: C1 | E7: 103/1000V | F7: CAP_DISC_200 | G7: 10% | H7: YAGEO,AVX,KEMET | I7: SAINI,HICOTRONICS,GUJARAT POLY AVX | J7: 0.6 | K7: =Table1479101156[[#This Row],[Unit Cost]]*Table1479101156[[#This Row],[Quantity]] -> 0.6 | L7: 0 | M7: =Table1479101156[[#This Row],[Quantity]]*Z7-Table1479101156[[#This Row],[STOCK]] -> 0 | N7: =IF(Table1479101156[[#This Row],[Interim Value]]<0,0,Table1479101156[[#This Row],[Interim Value]]) -> 0 | O7: =Table1479101156[[#This Row],[Kitting Quantity]]*Table1479101156[[#This Row],[Unit Cost]] -> 0 | P7: SUN MICRO COMPONENTS | Q7: 60DAYS CREDIT | Z7: =N1 -> 0
A8: 3 | B8: RS01080 | C8: 1 | D8: C3 | E8: 100P | F8: C0805 | G8: 5% | H8: YAGEO,AVX,KEMET | I8: SAINI,HICOTRONICS,GUJARAT POLY AVX | J8: 0.2 | K8: =Table1479101156[[#This Row],[Unit Cost]]*Table1479101156[[#This Row],[Quantity]] -> 0.2 | L8: 3715 | M8: =Table1479101156[[#This Row],[Quantity]]*Z8-Table1479101156[[#This Row],[STOCK]] -> -3715 | N8: =IF(Table1479101156[[#This Row],[Interim Value]]<0,0,Table1479101156[[#This Row],[Interim Value]]) -> 0 | O8: =Table1479101156[[#This Row],[Kitting Quantity]]*Table1479101156[[#This Row],[Unit Cost]] -> 0 | P8: HICOTRONICS | Q8: 60DAYS CREDIT | Z8: =N1 -> 0
A9: 4 | B9: RS01012 | C9: 1 | D9: C4 | E9: 1uF/50 | F9: C0805 | G9: 5% | H9: YAGEO,AVX,KEMET | I9: SAINI,HICOTRONICS,GUJARAT POLY AVX | J9: 0.35 | K9: =Table1479101156[[#This Row],[Unit Cost]]*Table1479101156[[#This Row],[Quantity]] -> 0.35 | L9: 1745 | M9: =Table1479101156[[#This Row],[Quantity]]*Z9-Table1479101156[[#This Row],[STOCK]] -> -1745 | N9: =IF(Table1479101156[[#This Row],[Interim Value]]<0,0,Table1479101156[[#This Row],[Interim Value]]) -> 0 | O9: =Table1479101156[[#This Row],[Kitting Quantity]]*Table1479101156[[#This Row],[Unit Cost]] -> 0 | P9: HICOTRONICS | Q9: 60DAYS CREDIT | Z9: =N1 -> 0
A10: 5 | B10: RS01012 | C10: 1 | D10: C5 | E10: 1uF/50 | F10: C0805 | G10: 5% | H10: YAGEO,AVX,KEMET | I10: SAINI,HICOTRONICS,GUJARAT POLY AVX | J10: 0.35 | K10: =Table1479101156[[#This Row],[Unit Cost]]*Table1479101156[[#This Row],[Quantity]] -> 0.35 | L10: 0 | M10: =Table1479101156[[#This Row],[Quantity]]*Z10-Table1479101156[[#This Row],[STOCK]] -> 0 | N10: =IF(Table1479101156[[#This Row],[Interim Value]]<0,0,Table1479101156[[#This Row],[Interim Value]]) -> 0 | O10: =Table1479101156[[#This Row],[Kitting Quantity]]*Table1479101156[[#This Row],[Unit Cost]] -> 0 | P10: HICOTRONICS | Q10: 60DAYS CREDIT | Z10: =N1 -> 0
A11: 6 | B11: CP04007 | C11: 1 | D11: C6 | E11: 103, 1KVA | F11: CAP_TH | G11: 10% | H11: YAGEO,AVX,KEMET | I11: SAINI,HICOTRONICS,GUJARAT POLY AVX | J11: 0.6 | K11: =Table1479101156[[#This Row],[Unit Cost]]*Table1479101156[[#This Row],[Quantity]] -> 0.6 | L11: 0 | M11: =Table1479101156[[#This Row],[Quantity]]*Z11-Table1479101156[[#This Row],[STOCK]] -> 0 | N11: =IF(Table1479101156[[#This Row],[Interim Value]]<0,0,Table1479101156[[#This Row],[Interim Value]]) -> 0 | O11: =Table1479101156[[#This Row],[Kitting Quantity]]*Table1479101156[[#This Row],[Unit Cost]] -> 0 | P11: SUN MICRO COMPONENTS | Q11: 60DAYS CREDIT | Z11: =N1 -> 0
A12: 7 | B12: CP04007 | C12: 1 | D12: C7 | E12: 103/1000V | F12: CAP_DISC_200 | G12: 10% | H12: YAGEO,AVX,KEMET | I12: SAINI,HICOTRONICS,GUJARAT POLY AVX | J12: 0.6 | K12: =Table1479101156[[#This Row],[Unit Cost]]*Table1479101156[[#This Row],[Quantity]] -> 0.6 | L12: 0 | M12: =Table1479101156[[#This Row],[Quantity]]*Z12-Table1479101156[[#This Row],[STOCK]] -> 0 | N12: =IF(Table1479101156[[#This Row],[Interim Value]]<0,0,Table1479101156[[#This Row],[Interim Value]]) -> 0 | O12: =Table1479101156[[#This Row],[Kitting Quantity]]*Table1479101156[[#This Row],[Unit Cost]] -> 0 | P12: SUN MICRO COMPONENTS | Q12: 60DAYS CREDIT | Z12: =N1 -> 0
A13: 8 | B13: CP04004 | C13: 1 | D13: C8 | E13: P2G102K | F13: CAP_CER_2P_8MM | G13: NC | H13: PIA | I13: SREE ELECTRONICS,TEXTONIC | J13: 0.8 | K13: =Table1479101156[[#This Row],[Unit Cost]]*Table1479101156[[#This Row],[Quantity]] -> 0.8 | L13: 0 | M13: =Table1479101156[[#This Row],[Quantity]]*Z13-Table1479101156[[#This Row],[STOCK]] -> 0 | N13: =IF(Table1479101156[[#This Row],[Interim Value]]<0,0,Table1479101156[[#This Row],[Interim Value]]) -> 0 | O13: =Table1479101156[[#This Row],[Kitting Quantity]]*Table1479101156[[#This Row],[Unit Cost]] -> 0 | P13: SHREE ELECTRONICS | Q13: 60DAYS PDC | Z13: =N1 -> 0
A14: 9 | B14: CP04023 | C14: 1 | D14: C9 | E14: 220nF/630V | F14: CAP_CER_2P_8MM | G14: 10% | H14: JACKCON,SAMHWA | I14: SAINI ,TEXONICS | J14: 4.5 | K14: =Table1479101156[[#This Row],[Unit Cost]]*Table1479101156[[#This Row],[Quantity]] -> 4.5 | L14: 2500 | M14: =Table1479101156[[#This Row],[Quantity]]*Z14-Table1479101156[[#This Row],[STOCK]] -> -2500 | N14: =IF(Table1479101156[[#This Row],[Interim Value]]<0,0,Table1479101156[[#This Row],[Interim Value]]) -> 0 | O14: =Table1479101156[[#This Row],[Kitting Quantity]]*Table1479101156[[#This Row],[Unit Cost]] -> 0 | P14: SUN MICRO COMPONENTS | Q14: 60DAYS CREDIT | Z14: =N1 -> 0
A15: 10 | B15: CP04024 | C15: 1 | D15: CP1 | E15: 22uF/250V | F15: CAP_EL_22_5_SL | G15: 10% | H15: JACKCON,SAMHWA | I15: SAINI ,TEXONICS | J15: 3.6 | K15: =Table1479101156[[#This Row],[Unit Cost]]*Table1479101156[[#This Row],[Quantity]] -> 3.6 | L15: 500 | M15: =Table1479101156[[#This Row],[Quantity]]*Z15-Table1479101156[[#This Row],[STOCK]] -> -500 | N15: =IF(Table1479101156[[#This Row],[Interim Value]]<0,0,Table1479101156[[#This Row],[Interim Value]]) -> 0 | O15: =Table1479101156[[#This Row],[Kitting Quantity]]*Table1479101156[[#This Row],[Unit Cost]] -> 0 | P15: SUN MICRO COMPONENTS | Q15: 60DAYS CREDIT | Z15: =N1 -> 0
A16: 11 | B16: CP04024 | C16: 1 | D16: CP2 | E16: 22uF/250V | F16: CAP_EL_22_5_SL | G16: 10% | H16: JACKCON,SAMHWA | I16: SAINI ,TEXONICS | J16: 3.6 | K16: =Table1479101156[[#This Row],[Unit Cost]]*Table1479101156[[#This Row],[Quantity]] -> 3.6 | L16: 0 | M16: =Table1479101156[[#This Row],[Quantity]]*Z16-Table1479101156[[#This Row],[STOCK]] -> 0 | N16: =IF(Table1479101156[[#This Row],[Interim Value]]<0,0,Table1479101156[[#This Row],[Interim Value]]) -> 0 | O16: =Table1479101156[[#This Row],[Kitting Quantity]]*Table1479101156[[#This Row],[Unit Cost]] -> 0 | P16: SUN MICRO COMPONENTS | Q16: 60DAYS CREDIT | Z16: =N1 -> 0
A17: 12 | B17: DE05013 | C17: 1 | D17: D1 | E17: MUR460 | F17: DI_550_SR3100 | H17: GOODARC,MIC,HY | I17: SAINI,HICOTRONICS,GUJARAT POLY AVX | J17: 3.5 | K17: =Table1479101156[[#This Row],[Unit Cost]]*Table1479101156[[#This Row],[Quantity]] -> 3.5 | L17: 745 | M17: =Table1479101156[[#This Row],[Quantity]]*Z17-Table1479101156[[#This Row],[STOCK]] -> -745 | N17: =IF(Table1479101156[[#This Row],[Interim Value]]<0,0,Table1479101156[[#This Row],[Interim Value]]) -> 0 | O17: =Table1479101156[[#This Row],[Kitting Quantity]]*Table1479101156[[#This Row],[Unit Cost]] -> 0 | P17: HICOTRONICS | Q17: 60DAYS CREDIT | Z17: =N1 -> 0
A18: 13 | B18: DE05006 | C18: 1 | D18: D2 | E18: SS4007 | F18: SMA | H18: GOODARC,MIC,HY | I18: SAINI,HICOTRONICS,GUJARAT POLY AVX | J18: 0.45 | K18: =Table1479101156[[#This Row],[Unit Cost]]*Table1479101156[[#This Row],[Quantity]] -> 0.45 | L18: 0 | M18: =Table1479101156[[#This Row],[Quantity]]*Z18-Table1479101156[[#This Row],[STOCK]] -> 0 | N18: =IF(Table1479101156[[#This Row],[Interim Value]]<0,0,Table1479101156[[#This Row],[Interim Value]]) -> 0 | O18: =Table1479101156[[#This Row],[Kitting Quantity]]*Table1479101156[[#This Row],[Unit Cost]] -> 0 | P18: HICOTRONICS | Q18: 60DAYS CREDIT | Z18: =N1 -> 0
A19: 14 | B19: DE05006 | C19: 1 | D19: D3 | E19: SS4007 | F19: SMA | H19: GOODARC,MIC,HY | I19: SAINI,HICOTRONICS,GUJARAT POLY AVX | J19: 0.45 | K19: =Table1479101156[[#This Row],[Unit Cost]]*Table1479101156[[#This Row],[Quantity]] -> 0.45 | L19: 0 | M19: =Table1479101156[[#This Row],[Quantity]]*Z19-Table1479101156[[#This Row],[STOCK]] -> 0 | N19: =IF(Table1479101156[[#This Row],[Interim Value]]<0,0,Table1479101156[[#This Row],[Interim Value]]) -> 0 | O19: =Table1479101156[[#This Row],[Kitting Quantity]]*Table1479101156[[#This Row],[Unit Cost]] -> 0 | P19: HICOTRONICS | Q19: 60DAYS CREDIT | Z19: =N1 -> 0
A20: 15 | B20: DE05006 | C20: 1 | D20: D4 | E20: SS4007 | F20: SMA | H20: GOODARC,MIC,HY | I20: SAINI,HICOTRONICS,GUJARAT POLY AVX | J20: 0.45 | K20: =Table1479101156[[#This Row],[Unit Cost]]*Table1479101156[[#This Row],[Quantity]] -> 0.45 | L20: 0 | M20: =Table1479101156[[#This Row],[Quantity]]*Z20-Table1479101156[[#This Row],[STOCK]] -> 0 | N20: =IF(Table1479101156[[#This Row],[Interim Value]]<0,0,Table1479101156[[#This Row],[Interim Value]]) -> 0 | O20: =Table1479101156[[#This Row],[Kitting Quantity]]*Table1479101156[[#This Row],[Unit Cost]] -> 0 | P20: HICOTRONICS | Q20: 60DAYS CREDIT | Z20: =N1 -> 0
A21: 16 | B21: DE05015 | C21: 1 | D21: F1 | E21: 1A, 250V | F21: FUSE_2P_6MM | H21: UCHI/PROTECTRON | I21: SAINI,PUNITH ELECTRONICS | J21: 2.5 | K21: =Table1479101156[[#This Row],[Unit Cost]]*Table1479101156[[#This Row],[Quantity]] -> 2.5 | L21: 0 | M21: =Table1479101156[[#This Row],[Quantity]]*Z21-Table1479101156[[#This Row],[STOCK]] -> 0 | N21: =IF(Table1479101156[[#This Row],[Interim Value]]<0,0,Table1479101156[[#This Row],[Interim Value]]) -> 0 | O21: =Table1479101156[[#This Row],[Kitting Quantity]]*Table1479101156[[#This Row],[Unit Cost]] -> 0 | P21: SUN MICRO COMPONENTS | Q21: 60DAYS CREDIT | Z21: =N1 -> 0
A22: 17 | B22: IN08003 | C22: 1 | D22: L4 | E22: 3mH | F22: IND_5MM_TH | G22: 5% | H22: METRONIX | I22: METRONIX | J22: 7.5 | K22: =Table1479101156[[#This Row],[Unit Cost]]*Table1479101156[[#This Row],[Quantity]] -> 7.5 | L22: 0 | M22: =Table1479101156[[#This Row],[Quantity]]*Z22-Table1479101156[[#This Row],[STOCK]] -> 0 | N22: =IF(Table1479101156[[#This Row],[Interim Value]]<0,0,Table1479101156[[#This Row],[Interim Value]]) -> 0 | O22: =Table1479101156[[#This Row],[Kitting Quantity]]*Table1479101156[[#This Row],[Unit Cost]] -> 0 | P22: METRONIX | Q22: 90 DAYS CREDIT | Z22: =N1 -> 0
A23: 18 | B23: IN08002 | C23: 1 | D23: L5 | E23: 1mH | F23: R_400 | H23: JMY | I23: JMY | J23: 0.9 | K23: =Table1479101156[[#This Row],[Unit Cost]]*Table1479101156[[#This Row],[Quantity]] -> 0.9 | L23: 7500 | M23: =Table1479101156[[#This Row],[Quantity]]*Z23-Table1479101156[[#This Row],[STOCK]] -> -7500 | N23: =IF(Table1479101156[[#This Row],[Interim Value]]<0,0,Table1479101156[[#This Row],[Interim Value]]) -> 0 | O23: =Table1479101156[[#This Row],[Kitting Quantity]]*Table1479101156[[#This Row],[Unit Cost]] -> 0 | P23: JMY | Q23: IMMEDIATE | Z23: =N1 -> 0
A24: 19 | B24: IN08002 | C24: 1 | D24: L6 | E24: 1mH | F24: R_400 | H24: JMY | I24: JMY | J24: 0.9 | K24: =Table1479101156[[#This Row],[Unit Cost]]*Table1479101156[[#This Row],[Quantity]] -> 0.9 | L24: 0 | M24: =Table1479101156[[#This Row],[Quantity]]*Z24-Table1479101156[[#This Row],[STOCK]] -> 0 | N24: =IF(Table1479101156[[#This Row],[Interim Value]]<0,0,Table1479101156[[#This Row],[Interim Value]]) -> 0 | O24: =Table1479101156[[#This Row],[Kitting Quantity]]*Table1479101156[[#This Row],[Unit Cost]] -> 0 | P24: JMY | Q24: IMMEDIATE | Z24: =N1 -> 0
A25: 20 | B25: IN08002 | C25: 1 | D25: L7 | E25: 1mH | F25: R_400 | H25: JMY | I25: JMY | J25: 0.9 | K25: =Table1479101156[[#This Row],[Unit Cost]]*Table1479101156[[#This Row],[Quantity]] -> 0.9 | L25: 0 | M25: =Table1479101156[[#This Row],[Quantity]]*Z25-Table1479101156[[#This Row],[STOCK]] -> 0 | N25: =IF(Table1479101156[[#This Row],[Interim Value]]<0,0,Table1479101156[[#This Row],[Interim Value]]) -> 0 | O25: =Table1479101156[[#This Row],[Kitting Quantity]]*Table1479101156[[#This Row],[Unit Cost]] -> 0 | P25: JMY | Q25: IMMEDIATE | Z25: =N1 -> 0
A26: 21 | B26: MOV11003 | C26: 1 | D26: MOV1 | E26: 14D471K | F26: RES_2W | H26: EPCOS/UCHI/HEL | I26: HICOTRONICS,SAINI | J26: 3 | K26: =Table1479101156[[#This Row],[Unit Cost]]*Table1479101156[[#This Row],[Quantity]] -> 3 | L26: 0 | M26: =Table1479101156[[#This Row],[Quantity]]*Z26-Table1479101156[[#This Row],[STOCK]] -> 0 | N26: =IF(Table1479101156[[#This Row],[Interim Value]]<0,0,Table1479101156[[#This Row],[Interim Value]]) -> 0 | O26: =Table1479101156[[#This Row],[Kitting Quantity]]*Table1479101156[[#This Row],[Unit Cost]] -> 0 | P26: SUN MICRO COMPONENTS | Q26: 60DAYS CREDIT | Z26: =N1 -> 0
A27: 22 | B27: MF02004 | C27: 1 | D27: Q1 | E27: H4N60 | F27: TO_220_AB_HOR | H27: FAIRCHILD ,HY ,SEM | I27: SAINI,SEM | J27: 11.9 | K27: =Table1479101156[[#This Row],[Unit Cost]]*Table1479101156[[#This Row],[Quantity]] -> 11.9 | L27: 0 | M27: =Table1479101156[[#This Row],[Quantity]]*Z27-Table1479101156[[#This Row],[STOCK]] -> 0 | N27: =IF(Table1479101156[[#This Row],[Interim Value]]<0,0,Table1479101156[[#This Row],[Interim Value]]) -> 0 | O27: =Table1479101156[[#This Row],[Kitting Quantity]]*Table1479101156[[#This Row],[Unit Cost]] -> 0 | P27: SUN MICRO COMPONENTS | Q27: 60DAYS CREDIT | Z27: =N1 -> 0
A28: 23 | B28: RS01009 | C28: 1 | D28: R1 | E28: 0R | F28: R0805 | H28: YAGEO,ROYALOHM ,UNIOHAM | I28: HICOTRONICS,GUJARAT POLY AVX,ELECTRONICA | J28: 0.05 | K28: =Table1479101156[[#This Row],[Unit Cost]]*Table1479101156[[#This Row],[Quantity]] -> 0.05 | L28: 1750 | M28: =Table1479101156[[#This Row],[Quantity]]*Z28-Table1479101156[[#This Row],[STOCK]] -> -1750 | N28: =IF(Table1479101156[[#This Row],[Interim Value]]<0,0,Table1479101156[[#This Row],[Interim Value]]) -> 0 | O28: =Table1479101156[[#This Row],[Kitting Quantity]]*Table1479101156[[#This Row],[Unit Cost]] -> 0 | P28: HICOTRONICS | Q28: 60DAYS CREDIT | Z28: =N1 -> 0
A29: 24 | B29: RS01106 | C29: 1 | D29: R2 | E29: 1R100 | F29: R1206 | G29: 1% | H29: YAGEO,ROYALOHM ,UNIOHAM | I29: HICOTRONICS,GUJARAT POLY AVX,ELECTRONICA | J29: 0.2 | K29: =Table1479101156[[#This Row],[Unit Cost]]*Table1479101156[[#This Row],[Quantity]] -> 0.2 | L29: 0 | M29: =Table1479101156[[#This Row],[Quantity]]*Z29-Table1479101156[[#This Row],[STOCK]] -> 0 | N29: =IF(Table1479101156[[#This Row],[Interim Value]]<0,0,Table1479101156[[#This Row],[Interim Value]]) -> 0 | O29: =Table1479101156[[#This Row],[Kitting Quantity]]*Table1479101156[[#This Row],[Unit Cost]] -> 0 | P29: HICOTRONICS | Q29: 60DAYS CREDIT | Z29: =N1 -> 0
A30: 25 | B30: RS01130 | C30: 1 | D30: R3 | E30: 0.68E | F30: R1206 | G30: 1% | H30: YAGEO,ROYALOHM ,UNIOHAM | I30: HICOTRONICS,GUJARAT POLY AVX,ELECTRONICA | J30: 0.5 | K30: =Table1479101156[[#This Row],[Unit Cost]]*Table1479101156[[#This Row],[Quantity]] -> 0.5 | L30: 2525 | M30: =Table1479101156[[#This Row],[Quantity]]*Z30-Table1479101156[[#This Row],[STOCK]] -> -2525 | N30: =IF(Table1479101156[[#This Row],[Interim Value]]<0,0,Table1479101156[[#This Row],[Interim Value]]) -> 0 | O30: =Table1479101156[[#This Row],[Kitting Quantity]]*Table1479101156[[#This Row],[Unit Cost]] -> 0 | P30: HICOTRONICS | Q30: 60DAYS CREDIT | Z30: =N1 -> 0
A31: 26 | B31: RS01092 | C31: 1 | D31: R4 | E31: 49.9K | F31: R0805 | G31: 1% | H31: YAGEO,ROYALOHM ,UNIOHAM | I31: HICOTRONICS,GUJARAT POLY AVX,ELECTRONICA | J31: 0.05 | K31: =Table1479101156[[#This Row],[Unit Cost]]*Table1479101156[[#This Row],[Quantity]] -> 0.05 | L31: 0 | M31: =Table1479101156[[#This Row],[Quantity]]*Z31-Table1479101156[[#This Row],[STOCK]] -> 0 | N31: =IF(Table1479101156[[#This Row],[Interim Value]]<0,0,Table1479101156[[#This Row],[Interim Value]]) -> 0 | O31: =Table1479101156[[#This Row],[Kitting Quantity]]*Table1479101156[[#This Row],[Unit Cost]] -> 0 | P31: HICOTRONICS | Q31: 60DAYS CREDIT | Z31: =N1 -> 0
A32: 27 | B32: RS01007 | C32: 1 | D32: R6 | E32: 100K | F32: R0805 | G32: 1% | H32: YAGEO,ROYALOHM ,UNIOHAM | I32: HICOTRONICS,GUJARAT POLY AVX,ELECTRONICA | J32: 0.05 | K32: =Table1479101156[[#This Row],[Unit Cost]]*Table1479101156[[#This Row],[Quantity]] -> 0.05 | L32: 0 | M32: =Table1479101156[[#This Row],[Quantity]]*Z32-Table1479101156[[#This Row],[STOCK]] -> 0 | N32: =IF(Table1479101156[[#This Row],[Interim Value]]<0,0,Table1479101156[[#This Row],[Interim Value]]) -> 0 | O32: =Table1479101156[[#This Row],[Kitting Quantity]]*Table1479101156[[#This Row],[Unit Cost]] -> 0 | P32: HICOTRONICS | Q32: 60DAYS CREDIT | Z32: =N1 -> 0
A33: 28 | B33: RS01090 | C33: 1 | D33: R7 | E33: 333K | F33: R0805 | G33: 1% | H33: YAGEO,ROYALOHM ,UNIOHAM | I33: HICOTRONICS,GUJARAT POLY AVX,ELECTRONICA | J33: 0.05 | K33: =Table1479101156[[#This Row],[Unit Cost]]*Table1479101156[[#This Row],[Quantity]] -> 0.05 | L33: 0 | M33: =Table1479101156[[#This Row],[Quantity]]*Z33-Table1479101156[[#This Row],[STOCK]] -> 0 | N33: =IF(Table1479101156[[#This Row],[Interim Value]]<0,0,Table1479101156[[#This Row],[Interim Value]]) -> 0 | O33: =Table1479101156[[#This Row],[Kitting Quantity]]*Table1479101156[[#This Row],[Unit Cost]] -> 0 | P33: HICOTRONICS | Q33: 60DAYS CREDIT | Z33: =N1 -> 0
A34: 29 | B34: RS01131 | C34: 1 | D34: R8 | E34: 10E | F34: R0805 | G34: 1% | H34: YAGEO,ROYALOHM ,UNIOHAM | I34: HICOTRONICS,GUJARAT POLY AVX,ELECTRONICA | J34: 0.05 | K34: =Table1479101156[[#This Row],[Unit Cost]]*Table1479101156[[#This Row],[Quantity]] -> 0.05 | L34: 4950 | M34: =Table1479101156[[#This Row],[Quantity]]*Z34-Table1479101156[[#This Row],[STOCK]] -> -4950 | N34: =IF(Table1479101156[[#This Row],[Interim Value]]<0,0,Table1479101156[[#This Row],[Interim Value]]) -> 0 | O34: =Table1479101156[[#This Row],[Kitting Quantity]]*Table1479101156[[#This Row],[Unit Cost]] -> 0 | P34: HICOTRONICS | Q34: 60DAYS CREDIT | Z34: =N1 -> 0
A35: 30 | B35: RS01094 | C35: 1 | D35: R10 | E35: 174KE | F35: R0603 | G35: 5% | H35: YAGEO,ROYALOHM ,UNIOHAM | I35: HICOTRONICS,GUJARAT POLY AVX,ELECTRONICA | J35: 0.05 | K35: =Table1479101156[[#This Row],[Unit Cost]]*Table1479101156[[#This Row],[Quantity]] -> 0.05 | L35: 0 | M35: =Table1479101156[[#This Row],[Quantity]]*Z35-Table1479101156[[#This Row],[STOCK]] -> 0 | N35: =IF(Table1479101156[[#This Row],[Interim Value]]<0,0,Table1479101156[[#This Row],[Interim Value]]) -> 0 | O35: =Table1479101156[[#This Row],[Kitting Quantity]]*Table1479101156[[#This Row],[Unit Cost]] -> 0 | P35: HICOTRONICS | Q35: 60DAYS CREDIT | Z35: =N1 -> 0
A36: 31 | B36: RS01095 | C36: 1 | D36: R11 | E36: 1K | F36: R0603 | G36: NC | H36: YAGEO,ROYALOHM ,UNIOHAM | I36: HICOTRONICS,GUJARAT POLY AVX,ELECTRONICA | J36: 0.05 | K36: =Table1479101156[[#This Row],[Unit Cost]]*Table1479101156[[#This Row],[Quantity]] -> 0.05 | L36: 2615 | M36: =Table1479101156[[#This Row],[Quantity]]*Z36-Table1479101156[[#This Row],[STOCK]] -> -2615 | N36: =IF(Table1479101156[[#This Row],[Interim Value]]<0,0,Table1479101156[[#This Row],[Interim Value]]) -> 0 | O36: =Table1479101156[[#This Row],[Kitting Quantity]]*Table1479101156[[#This Row],[Unit Cost]] -> 0 | P36: HICOTRONICS | Q36: 60DAYS CREDIT | Z36: =N1 -> 0
A37: 32 | B37: RS01030 | C37: 1 | D37: R12 | E37: 430E | F37: R0805 | G37: 5% | H37: YAGEO,ROYALOHM ,UNIOHAM | I37: HICOTRONICS,GUJARAT POLY AVX,ELECTRONICA | J37: 0.05 | K37: =Table1479101156[[#This Row],[Unit Cost]]*Table1479101156[[#This Row],[Quantity]] -> 0.05 | L37: 0 | M37: =Table1479101156[[#This Row],[Quantity]]*Z37-Table1479101156[[#This Row],[STOCK]] -> 0 | N37: =IF(Table1479101156[[#This Row],[Interim Value]]<0,0,Table1479101156[[#This Row],[Interim Value]]) -> 0 | O37: =Table1479101156[[#This Row],[Kitting Quantity]]*Table1479101156[[#This Row],[Unit Cost]] -> 0 | P37: HICOTRONICS | Q37: 60DAYS CREDIT | Z37: =N1 -> 0
A38: 33 | B38: RS01107 | C38: 1 | D38: R13 | E38: 7.5k | F38: 1/4 WATT | G38: 5% | H38: YAGEO,ROYALOHM ,UNIOHAM | I38: HICOTRONICS,GUJARAT POLY AVX,ELECTRONICA | J38: 0.05 | K38: =Table1479101156[[#This Row],[Unit Cost]]*Table1479101156[[#This Row],[Quantity]] -> 0.05 | L38: 2500 | M38: =Table1479101156[[#This Row],[Quantity]]*Z38-Table1479101156[[#This Row],[STOCK]] -> -2500 | N38: =IF(Table1479101156[[#This Row],[Interim Value]]<0,0,Table1479101156[[#This Row],[Interim Value]]) -> 0 | O38: =Table1479101156[[#This Row],[Kitting Quantity]]*Table1479101156[[#This Row],[Unit Cost]] -> 0 | P38: SHREE ELECTRONICS | Q38: 60DAYS PDC | Z38: =N1 -> 0
A39: 34 | B39: RS01132 | C39: 1 | D39: R14 | E39: 1E | F39: RES_1W | G39: 1 | H39: YAGEO,ROYALOHM ,UNIOHAM | I39: HICOTRONICS,GUJARAT POLY AVX,ELECTRONICA | J39: 1 | K39: =Table1479101156[[#This Row],[Unit Cost]]*Table1479101156[[#This Row],[Quantity]] -> 1 | L39: 2500 | M39: =Table1479101156[[#This Row],[Quantity]]*Z39-Table1479101156[[#This Row],[STOCK]] -> -2500 | N39: =IF(Table1479101156[[#This Row],[Interim Value]]<0,0,Table1479101156[[#This Row],[Interim Value]]) -> 0 | O39: =Table1479101156[[#This Row],[Kitting Quantity]]*Table1479101156[[#This Row],[Unit Cost]] -> 0 | P39: JMY | Q39: IMMEDIATE | Z39: =N1 -> 0
A40: 35 | C40: 1 | D40: RT1 | E40: NTC | F40: RES_2W | J40: 1 | K40: =Table1479101156[[#This Row],[Unit Cost]]*Table1479101156[[#This Row],[Quantity]] -> 1 | L40: 0 | M40: =Table1479101156[[#This Row],[Quantity]]*Z40-Table1479101156[[#This Row],[STOCK]] -> 0 | N40: =IF(Table1479101156[[#This Row],[Interim Value]]<0,0,Table1479101156[[#This Row],[Interim Value]]) -> 0 | O40: =Table1479101156[[#This Row],[Kitting Quantity]]*Table1479101156[[#This Row],[Unit Cost]] -> 0 | Q40: 60DAYS CREDIT | Z40: =N1 -> 0
A41: 36 | B41: IC15001 | C41: 1 | D41: U1 | E41: SM3300 | F41: SO8 | H41: SEMTRONICS | I41: SEM | J41: 15 | K41: =Table1479101156[[#This Row],[Unit Cost]]*Table1479101156[[#This Row],[Quantity]] -> 15 | L41: 2500 | M41: =Table1479101156[[#This Row],[Quantity]]*Z41-Table1479101156[[#This Row],[STOCK]] -> -2500 | N41: =IF(Table1479101156[[#This Row],[Interim Value]]<0,0,Table1479101156[[#This Row],[Interim Value]]) -> 0 | O41: =Table1479101156[[#This Row],[Kitting Quantity]]*Table1479101156[[#This Row],[Unit Cost]] -> 0 | P41: SEM | Q41: IMMEDIATE | Z41: =N1 -> 0
A42: 37 | B42: PCB09035 | C42: 1 | E42: PCB | I42: UNIVERSAL | J42: 17.5 | K42: =Table1479101156[[#This Row],[Unit Cost]]*Table1479101156[[#This Row],[Quantity]] -> 17.5 | L42: 4043 | M42: =Table1479101156[[#This Row],[Quantity]]*Z42-Table1479101156[[#This Row],[STOCK]] -> -4043 | N42: =IF(Table1479101156[[#This Row],[Interim Value]]<0,0,Table1479101156[[#This Row],[Interim Value]]) -> 0 | O42: =Table1479101156[[#This Row],[Kitting Quantity]]*Table1479101156[[#This Row],[Unit Cost]] -> 0 | P42: UNIVERSAL CIRCUTS | Q42: 60DAYS | Z42: =N1 -> 0
...

Sheet TL 5.13 VER
A1: Product Code | C1: DR13081 | K1: Kitting Quantity | N1: ='Detail-Planner'!E7 -> 0
A3: Product Description - 45V 700mA (17~30W Compatible) TL 5.13 VER
A5: Item | B5: Raw Material Code | C5: Quantity | D5: Reference | E5: Part | F5: Package | G5: Tolerence | H5: Make | I5: Vendor | J5: Unit Cost | K5: TOTAL | L5: STOCK | M5: Interim Value | N5: Kitting Quantity | O5: PRICE | P5: SUPPLIER NAME | Q5: PAYMENT TERMS
A6: 1 | B6: DE05001 | C6: 1 | D6: BD1 | E6: B10S-G(1000V 1A) | F6: TO-269AA | G6: 10% | H6: GOODARC,MIC,HY | I6: HICOTRONICS,MIC,SAINI | J6: 2.6 | K6: =Table14[[#This Row],[Unit Cost]]*Table14[[#This Row],[Quantity]] -> 2.6 | L6: 0 | M6: =Table14[[#This Row],[Quantity]]*Z6-Table14[[#This Row],[STOCK]] -> 0 | N6: =IF(Table14[[#This Row],[Interim Value]]<0,0,Table14[[#This Row],[Interim Value]]) -> 0 | O6: =Table14[[#This Row],[Kitting Quantity]]*Table14[[#This Row],[TOTAL]] -> 0 | P6: HICOTRONICS | Q6: 60DAYS CREDIT | Z6: =N1 -> 0
A7: 2 | B7: CP04007 | C7: 3 | D7: C1,C6,C7 | E7: 103/1000V | F7: CAP_DISC_200 | G7: 10% | H7: HEL / JACKCON/GUJARAT POLY AVX | I7: SAINI,HICOTRONICS,GUJARAT POLY AVX | J7: 0.6 | K7: =Table14[[#This Row],[Unit Cost]]*Table14[[#This Row],[Quantity]] -> 1.8 | L7: 0 | M7: =Table14[[#This Row],[Quantity]]*Z7-Table14[[#This Row],[STOCK]] -> 0 | N7: =IF(Table14[[#This Row],[Interim Value]]<0,0,Table14[[#This Row],[Interim Value]]) -> 0 | O7: =Table14[[#This Row],[Kitting Quantity]]*Table14[[#This Row],[TOTAL]] -> 0 | P7: SUN MICRO COMPONENTS | Q7: 60DAYS CREDIT | Z7: =N1 -> 0
A8: 3 | B8: RS01080 | C8: 1 | D8: C3 | E8: 100P/50V | F8: C0805 | G8: 5% | H8: YAGEO,AVX,KEMET | I8: SAINI,HICOTRONICS,GUJARAT POLY AVX | J8: 0.2 | K8: =Table14[[#This Row],[Unit Cost]]*Table14[[#This Row],[Quantity]] -> 0.2 | L8: 0 | M8: =Table14[[#This Row],[Quantity]]*Z8-Table14[[#This Row],[STOCK]] -> 0 | N8: =IF(Table14[[#This Row],[Interim Value]]<0,0,Table14[[#This Row],[Interim Value]]) -> 0 | O8: =Table14[[#This Row],[Kitting Quantity]]*Table14[[#This Row],[TOTAL]] -> 0 | P8: HICOTRONICS | Q8: 60DAYS CREDIT | Z8: =N1 -> 0
A9: 4 | B9: RS01012 | C9: 1 | D9: C4 | E9: 1uF/50V | F9: C0805 | G9: 5% | H9: YAGEO,AVX,KEMET | I9: SAINI,HICOTRONICS,GUJARAT POLY AVX | J9: 0.35 | K9: =Table14[[#This Row],[Unit Cost]]*Table14[[#This Row],[Quantity]] -> 0.35 | L9: 0 | M9: =Table14[[#This Row],[Quantity]]*Z9-Table14[[#This Row],[STOCK]] -> 0 | N9: =IF(Table14[[#This Row],[Interim Value]]<0,0,Table14[[#This Row],[Interim Value]]) -> 0 | O9: =Table14[[#This Row],[Kitting Quantity]]*Table14[[#This Row],[TOTAL]] -> 0 | P9: HICOTRONICS | Q9: 60DAYS CREDIT | Z9: =N1 -> 0
A10: 5 | B10: RS01091 | C10: 1 | D10: C5 | E10: 100nF/50V | F10: C0805 | G10: 5% | H10: YAGEO,AVX,KEMET | I10: SAINI,HICOTRONICS,GUJARAT POLY AVX | J10: 0.2 | K10: =Table14[[#This Row],[Unit Cost]]*Table14[[#This Row],[Quantity]] -> 0.2 | L10: 0 | M10: =Table14[[#This Row],[Quantity]]*Z10-Table14[[#This Row],[STOCK]] -> 0 | N10: =IF(Table14[[#This Row],[Interim Value]]<0,0,Table14[[#This Row],[Interim Value]]) -> 0 | O10: =Table14[[#This Row],[Kitting Quantity]]*Table14[[#This Row],[TOTAL]] -> 0 | P10: HICOTRONICS | Q10: 60DAYS CREDIT | Z10: =N1 -> 0
A11: 6 | B11: CP04004 | C11: 1 | D11: C8 | E11: P2G102K | F11: CAP_CER_2P_8MM | G11: NC | H11: PIA | I11: SREE ELECTRONICS,TEXTONIC | J11: 0.8 | K11: =Table14[[#This Row],[Unit Cost]]*Table14[[#This Row],[Quantity]] -> 0.8 | L11: 0 | M11: =Table14[[#This Row],[Quantity]]*Z11-Table14[[#This Row],[STOCK]] -> 0 | N11: =IF(Table14[[#This Row],[Interim Value]]<0,0,Table14[[#This Row],[Interim Value]]) -> 0 | O11: =Table14[[#This Row],[Kitting Quantity]]*Table14[[#This Row],[TOTAL]] -> 0 | P11: SHREE ELECTRONICS | Q11: 60DAYS PDC | Z11: =N1 -> 0
A12: 7 | B12: CP04023 | C12: 1 | D12: C9 | E12: 220nF/630V | F12: CBB22-224J | G12: 10% | H12: JACKCON,SAMHWA | I12: SAINI ,TEXONICS | J12: 4.5 | K12: =Table14[[#This Row],[Unit Cost]]*Table14[[#This Row],[Quantity]] -> 4.5 | L12: 350 | M12: =Table14[[#This Row],[Quantity]]*Z12-Table14[[#This Row],[STOCK]] -> -350 | N12: =IF(Table14[[#This Row],[Interim Value]]<0,0,Table14[[#This Row],[Interim Value]]) -> 0 | O12: =Table14[[#This Row],[Kitting Quantity]]*Table14[[#This Row],[TOTAL]] -> 0 | P12: SUN MICRO COMPONENTS | Q12: 60DAYS CREDIT | Z12: =N1 -> 0
A13: 8 | B13: CP04024 | C13: 2 | D13: CP1,CP2 | E13: 22uF/250V(105) | F13: (10mm*17mm) | G13: 10% | H13: JACKCON,SAMHWA | I13: SAINI ,TEXONICS | J13: 3.6 | K13: =Table14[[#This Row],[Unit Cost]]*Table14[[#This Row],[Quantity]] -> 7.2 | L13: 0 | M13: =Table14[[#This Row],[Quantity]]*Z13-Table14[[#This Row],[STOCK]] -> 0 | N13: =IF(Table14[[#This Row],[Interim Value]]<0,0,Table14[[#This Row],[Interim Value]]) -> 0 | O13: =Table14[[#This Row],[Kitting Quantity]]*Table14[[#This Row],[TOTAL]] -> 0 | P13: SUN MICRO COMPONENTS | Q13: 60DAYS CREDIT | Z13: =N1 -> 0
A14: 9 | B14: DE05013 | C14: 1 | D14: D1 | E14: MUR460 | F14: D0-201AD | H14: GOODARC,MIC,HY | I14: SAINI,HICOTRONICS,GUJARAT POLY AVX | J14: 3.5 | K14: =Table14[[#This Row],[Unit Cost]]*Table14[[#This Row],[Quantity]] -> 3.5 | L14: 0 | M14: =Table14[[#This Row],[Quantity]]*Z14-Table14[[#This Row],[STOCK]] -> 0 | N14: =IF(Table14[[#This Row],[Interim Value]]<0,0,Table14[[#This Row],[Interim Value]]) -> 0 | O14: =Table14[[#This Row],[Kitting Quantity]]*Table14[[#This Row],[TOTAL]] -> 0 | P14: HICOTRONICS | Q14: 60DAYS CREDIT | Z14: =N1 -> 0
A15: 10 | B15: DE05006 | C15: 3 | D15: D2,D3,D4 | E15: SS4007 | F15: SMA | H15: GOODARC,MIC,HY | I15: SAINI,HICOTRONICS,GUJARAT POLY AVX | J15: 0.45 | K15: =Table14[[#This Row],[Unit Cost]]*Table14[[#This Row],[Quantity]] -> 1.35 | L15: 0 | M15: =Table14[[#This Row],[Quantity]]*Z15-Table14[[#This Row],[STOCK]] -> 0 | N15: =IF(Table14[[#This Row],[Interim Value]]<0,0,Table14[[#This Row],[Interim Value]]) -> 0 | O15: =Table14[[#This Row],[Kitting Quantity]]*Table14[[#This Row],[TOTAL]] -> 0 | P15: HICOTRONICS | Q15: 60DAYS CREDIT | Z15: =N1 -> 0
A16: 11 | B16: CR18007 | C16: 1 | D16: F1 | E16: 1A, 250V | F16: (3.6mm*10mm) | H16: UCHI/PROTECTRON | I16: SAINI,PUNITH ELECTRONICS | J16: 2.5 | K16: =Table14[[#This Row],[Unit Cost]]*Table14[[#This Row],[Quantity]] -> 2.5 | L16: 0 | M16: =Table14[[#This Row],[Quantity]]*Z16-Table14[[#This Row],[STOCK]] -> 0 | N16: =IF(Table14[[#This Row],[Interim Value]]<0,0,Table14[[#This Row],[Interim Value]]) -> 0 | O16: =Table14[[#This Row],[Kitting Quantity]]*Table14[[#This Row],[TOTAL]] -> 0 | P16: SUN MICRO COMPONENTS | Q16: 60DAYS CREDIT | Z16: =N1 -> 0
A17: 12 | B17: IN08014 | C17: 2 | D17: L4,L8 | E17: 2.4mH(600mA) | F17: EE16 VERTICAL | G17: 5% | H17: METRONIX | I17: METRONIX | J17: 7.5 | K17: =Table14[[#This Row],[Unit Cost]]*Table14[[#This Row],[Quantity]] -> 15 | L17: 0 | M17: =Table14[[#This Row],[Quantity]]*Z17-Table14[[#This Row],[STOCK]] -> 0 | N17: =IF(Table14[[#This Row],[Interim Value]]<0,0,Table14[[#This Row],[Interim Value]]) -> 0 | O17: =Table14[[#This Row],[Kitting Quantity]]*Table14[[#This Row],[TOTAL]] -> 0 | P17: METRONIX | Q17: 90 DAYS CREDIT | Z17: =N1 -> 0
A18: 13 | B18: IN08002 | C18: 2 | D18: L5,L6, | E18: 1mH | F18: 5mm*10.5mm | H18: JMY | I18: JMY | J18: 0.9 | K18: =Table14[[#This Row],[Unit Cost]]*Table14[[#This Row],[Quantity]] -> 1.8 | L18: 24346 | M18: =Table14[[#This Row],[Quantity]]*Z18-Table14[[#This Row],[STOCK]] -> -24346 | N18: =IF(Table14[[#This Row],[Interim Value]]<0,0,Table14[[#This Row],[Interim Value]]) -> 0 | O18: =Table14[[#This Row],[Kitting Quantity]]*Table14[[#This Row],[TOTAL]] -> 0 | P18: JMY | Q18: IMMEDIATE | Z18: =N1 -> 0
A19: 14 | B19: IN08002 | C19: 2 | D19: L7(OVER LAP) | E19: 1mH | F19: 5mm*10.5mm | H19: JMY | I19: JMY | J19: 0.9 | K19: =Table14[[#This Row],[Unit Cost]]*Table14[[#This Row],[Quantity]] -> 1.8 | L19: 0 | M19: =Table14[[#This Row],[Quantity]]*Z19-Table14[[#This Row],[STOCK]] -> 0 | N19: =IF(Table14[[#This Row],[Interim Value]]<0,0,Table14[[#This Row],[Interim Value]]) -> 0 | O19: =Table14[[#This Row],[Kitting Quantity]]*Table14[[#This Row],[TOTAL]] -> 0 | P19: JMY | Q19: IMMEDIATE | Z19: =N1 -> 0
A20: 15 | B20: MOV11003 | C20: 1 | D20: MOV1 | E20: 14D471K | F20: 14mm | H20: EPCOS/UCHI/HEL | I20: HICOTRONICS,SAINI | J20: 3 | K20: =Table14[[#This Row],[Unit Cost]]*Table14[[#This Row],[Quantity]] -> 3 | L20: 0 | M20: =Table14[[#This Row],[Quantity]]*Z20-Table14[[#This Row],[STOCK]] -> 0 | N20: =IF(Table14[[#This Row],[Interim Value]]<0,0,Table14[[#This Row],[Interim Value]]) -> 0 | O20: =Table14[[#This Row],[Kitting Quantity]]*Table14[[#This Row],[TOTAL]] -> 0 | P20: SUN MICRO COMPONENTS | Q20: 60DAYS CREDIT | Z20: =N1 -> 0
A21: 16 | B21: MF02004 | C21: 1 | D21: Q1 | E21: H4N65 | F21: TO-252 | H21: FAIRCHILD ,HY ,SEM | I21: SAINI,SEM | J21: 11.9 | K21: =Table14[[#This Row],[Unit Cost]]*Table14[[#This Row],[Quantity]] -> 11.9 | L21: 0 | M21: =Table14[[#This Row],[Quantity]]*Z21-Table14[[#This Row],[STOCK]] -> 0 | N21: =IF(Table14[[#This Row],[Interim Value]]<0,0,Table14[[#This Row],[Interim Value]]) -> 0 | O21: =Table14[[#This Row],[Kitting Quantity]]*Table14[[#This Row],[TOTAL]] -> 0 | P21: SUN MICRO COMPONENTS | Q21: 60DAYS CREDIT | Z21: =N1 -> 0
A22: 17 | B22: RS01172 | C22: 1 | D22: R1 | E22: 0R | F22: R1206 | G22: 1% | H22: YAGEO,ROYALOHM ,UNIOHAM | I22: HICOTRONICS,GUJARAT POLY AVX,ELECTRONICA | J22: 0.05 | K22: =Table14[[#This Row],[Unit Cost]]*Table14[[#This Row],[Quantity]] -> 0.05 | L22: 0 | M22: =Table14[[#This Row],[Quantity]]*Z22-Table14[[#This Row],[STOCK]] -> 0 | N22: =IF(Table14[[#This Row],[Interim Value]]<0,0,Table14[[#This Row],[Interim Value]]) -> 0 | O22: =Table14[[#This Row],[Kitting Quantity]]*Table14[[#This Row],[TOTAL]] -> 0 | P22: HICOTRONICS | Q22: 60DAYS CREDIT | Z22: =N1 -> 0
A23: 18 | B23: RS01173 | C23: 1 | D23: R2 | E23: R680 | F23: R1206 | G23: 1% | H23: YAGEO,ROYALOHM ,UNIOHAM | I23: HICOTRONICS,GUJARAT POLY AVX,ELECTRONICA | J23: 0.5 | K23: =Table14[[#This Row],[Unit Cost]]*Table14[[#This Row],[Quantity]] -> 0.5 | L23: 0 | M23: =Table14[[#This Row],[Quantity]]*Z23-Table14[[#This Row],[STOCK]] -> 0 | N23: =IF(Table14[[#This Row],[Interim Value]]<0,0,Table14[[#This Row],[Interim Value]]) -> 0 | O23: =Table14[[#This Row],[Kitting Quantity]]*Table14[[#This Row],[TOTAL]] -> 0 | P23: HICOTRONICS | Q23: 60DAYS CREDIT | Z23: =N1 -> 0
A24: 19 | B24: RS01173 | C24: 1 | D24: R3 | E24: R680 | F24: R1206 | G24: 1% | H24: YAGEO,ROYALOHM ,UNIOHAM | I24: HICOTRONICS,GUJARAT POLY AVX,ELECTRONICA | J24: 0.5 | K24: =Table14[[#This Row],[Unit Cost]]*Table14[[#This Row],[Quantity]] -> 0.5 | L24: 0 | M24: =Table14[[#This Row],[Quantity]]*Z24-Table14[[#This Row],[STOCK]] -> 0 | N24: =IF(Table14[[#This Row],[Interim Value]]<0,0,Table14[[#This Row],[Interim Value]]) -> 0 | O24: =Table14[[#This Row],[Kitting Quantity]]*Table14[[#This Row],[TOTAL]] -> 0 | P24: HICOTRONICS | Q24: 60DAYS CREDIT | Z24: =N1 -> 0
A25: 20 | B25: RS01174 | C25: 1 | D25: R4 | E25: 50K | F25: R1206 | G25: 1% | H25: YAGEO,ROYALOHM ,UNIOHAM | I25: HICOTRONICS,GUJARAT POLY AVX,ELECTRONICA | J25: 0.05 | K25: =Table14[[#This Row],[Unit Cost]]*Table14[[#This Row],[Quantity]] -> 0.05 | L25: 0 | M25: =Table14[[#This Row],[Quantity]]*Z25-Table14[[#This Row],[STOCK]] -> 0 | N25: =IF(Table14[[#This Row],[Interim Value]]<0,0,Table14[[#This Row],[Interim Value]]) -> 0 | O25: =Table14[[#This Row],[Kitting Quantity]]*Table14[[#This Row],[TOTAL]] -> 0 | P25: HICOTRONICS | Q25: 60DAYS CREDIT | Z25: =N1 -> 0
A26: 21 | C26: 1 | D26: R5 | E26: NC | F26: R0603 | H26: YAGEO,ROYALOHM ,UNIOHAM | I26: HICOTRONICS,GUJARAT POLY AVX,ELECTRONICA | J26: 0 | K26: =Table14[[#This Row],[Unit Cost]]*Table14[[#This Row],[Quantity]] -> 0 | L26: 0 | M26: =Table14[[#This Row],[Quantity]]*Z26-Table14[[#This Row],[STOCK]] -> 0 | N26: =IF(Table14[[#This Row],[Interim Value]]<0,0,Table14[[#This Row],[Interim Value]]) -> 0 | O26: =Table14[[#This Row],[Kitting Quantity]]*Table14[[#This Row],[TOTAL]] -> 0 | P26: HICOTRONICS | Q26: 60DAYS CREDIT | Z26: =N1 -> 0
A27: 22 | B27: RS01110 | C27: 1 | D27: R6 | E27: 100K | F27: R1206 | G27: 1% | H27: YAGEO,ROYALOHM ,UNIOHAM | I27: HICOTRONICS,GUJARAT POLY AVX,ELECTRONICA | J27: 0.05 | K27: =Table14[[#This Row],[Unit Cost]]*Table14[[#This Row],[Quantity]] -> 0.05 | L27: 0 | M27: =Table14[[#This Row],[Quantity]]*Z27-Table14[[#This Row],[STOCK]] -> 0 | N27: =IF(Table14[[#This Row],[Interim Value]]<0,0,Table14[[#This Row],[Interim Value]]) -> 0 | O27: =Table14[[#This Row],[Kitting Quantity]]*Table14[[#This Row],[TOTAL]] -> 0 | P27: HICOTRONICS | Q27: 60DAYS CREDIT | Z27: =N1 -> 0
A28: 23 | B28: RS01175 | C28: 1 | D28: R7 | E28: 510K | F28: R1206 | G28: 1% | H28: YAGEO,ROYALOHM ,UNIOHAM | I28: HICOTRONICS,GUJARAT POLY AVX,ELECTRONICA | J28: 0.05 | K28: =Table14[[#This Row],[Unit Cost]]*Table14[[#This Row],[Quantity]] -> 0.05 | L28: 0 | M28: =Table14[[#This Row],[Quantity]]*Z28-Table14[[#This Row],[STOCK]] -> 0 | N28: =IF(Table14[[#This Row],[Interim Value]]<0,0,Table14[[#This Row],[Interim Value]]) -> 0 | O28: =Table14[[#This Row],[Kitting Quantity]]*Table14[[#This Row],[TOTAL]] -> 0 | P28: HICOTRONICS | Q28: 60DAYS CREDIT | Z28: =N1 -> 0
A29: 24 | B29: RS01176 | C29: 1 | D29: R8 | E29: 10E | F29: R1206 | G29: 1% | H29: YAGEO,ROYALOHM ,UNIOHAM | I29: HICOTRONICS,GUJARAT POLY AVX,ELECTRONICA | J29: 0.05 | K29: =Table14[[#This Row],[Unit Cost]]*Table14[[#This Row],[Quantity]] -> 0.05 | L29: 0 | M29: =Table14[[#This Row],[Quantity]]*Z29-Table14[[#This Row],[STOCK]] -> 0 | N29: =IF(Table14[[#This Row],[Interim Value]]<0,0,Table14[[#This Row],[Interim Value]]) -> 0 | O29: =Table14[[#This Row],[Kitting Quantity]]*Table14[[#This Row],[TOTAL]] -> 0 | P29: HICOTRONICS | Q29: 60DAYS CREDIT | Z29: =N1 -> 0
A30: 25 | B30: RS01177 | C30: 1 | D30: R10 | E30: 174KE | F30: R1206 | G30: 5% | H30: YAGEO,ROYALOHM ,UNIOHAM | I30: HICOTRONICS,GUJARAT POLY AVX,ELECTRONICA | J30: 0.05 | K30: =Table14[[#This Row],[Unit Cost]]*Table14[[#This Row],[Quantity]] -> 0.05 | L30: 0 | M30: =Table14[[#This Row],[Quantity]]*Z30-Table14[[#This Row],[STOCK]] -> 0 | N30: =IF(Table14[[#This Row],[Interim Value]]<0,0,Table14[[#This Row],[Interim Value]]) -> 0 | O30: =Table14[[#This Row],[Kitting Quantity]]*Table14[[#This Row],[TOTAL]] -> 0 | P30: HICOTRONICS | Q30: 60DAYS CREDIT | Z30: =N1 -> 0
A31: 26 | B31: RS01095 | C31: 1 | D31: R11 | E31: 1K | F31: R0603 | G31: NC | H31: YAGEO,ROYALOHM ,UNIOHAM | I31: HICOTRONICS,GUJARAT POLY AVX,ELECTRONICA | J31: 0.05 | K31: =Table14[[#This Row],[Unit Cost]]*Table14[[#This Row],[Quantity]] -> 0.05 | L31: 0 | M31: =Table14[[#This Row],[Quantity]]*Z31-Table14[[#This Row],[STOCK]] -> 0 | N31: =IF(Table14[[#This Row],[Interim Value]]<0,0,Table14[[#This Row],[Interim Value]]) -> 0 | O31: =Table14[[#This Row],[Kitting Quantity]]*Table14[[#This Row],[TOTAL]] -> 0 | P31: HICOTRONICS | Q31: 60DAYS CREDIT | Z31: =N1 -> 0
A32: 27 | B32: RS01178 | C32: 1 | D32: R12 | E32: 430E | F32: R1206 | G32: 5% | H32: YAGEO,ROYALOHM ,UNIOHAM | I32: HICOTRONICS,GUJARAT POLY AVX,ELECTRONICA | J32: 0.05 | K32: =Table14[[#This Row],[Unit Cost]]*Table14[[#This Row],[Quantity]] -> 0.05 | L32: 0 | M32: =Table14[[#This Row],[Quantity]]*Z32-Table14[[#This Row],[STOCK]] -> 0 | N32: =IF(Table14[[#This Row],[Interim Value]]<0,0,Table14[[#This Row],[Interim Value]]) -> 0 | O32: =Table14[[#This Row],[Kitting Quantity]]*Table14[[#This Row],[TOTAL]] -> 0 | P32: HICOTRONICS | Q32: 60DAYS CREDIT | Z32: =N1 -> 0
A33: 28 | B33: DE05014 | C33: 1 | D33: POT1 | E33: 10K | F33: TRIMMER | G33: 5% | H33: YAGEO,ROYALOHM ,UNIOHAM | I33: HICOTRONICS,GUJARAT POLY AVX,ELECTRONICA | J33: 1.6 | K33: =Table14[[#This Row],[Unit Cost]]*Table14[[#This Row],[Quantity]] -> 1.6 | L33: 0 | M33: =Table14[[#This Row],[Quantity]]*Z33-Table14[[#This Row],[STOCK]] -> 0 | N33: =IF(Table14[[#This Row],[Interim Value]]<0,0,Table14[[#This Row],[Interim Value]]) -> 0 | O33: =Table14[[#This Row],[Kitting Quantity]]*Table14[[#This Row],[TOTAL]] -> 0 | P33: HICOTRONICS | Q33: 60DAYS CREDIT | Z33: =N1 -> 0
A34: 29 | B34: RS01179 | C34: 1 | D34: R14 | E34: 1E | F34: 1/2W AXIAL | G34: 5% | H34: AVX,YAGEO | J34: 1 | K34: =Table14[[#This Row],[Unit Cost]]*Table14[[#This Row],[Quantity]] -> 1 | L34: 0 | M34: =Table14[[#This Row],[Quantity]]*Z34-Table14[[#This Row],[STOCK]] -> 0 | N34: =IF(Table14[[#This Row],[Interim Value]]<0,0,Table14[[#This Row],[Interim Value]]) -> 0 | O34: =Table14[[#This Row],[Kitting Quantity]]*Table14[[#This Row],[TOTAL]] -> 0 | P34: JMY | Q34: IMMEDIATE | Z34: =N1 -> 0
A35: 30 | B35: THM11010 | C35: 1 | D35: RT1 | E35: NTC | F35: RES_2W | J35: 2 | K35: =Table14[[#This Row],[Unit Cost]]*Table14[[#This Row],[Quantity]] -> 2 | L35: 0 | M35: =Table14[[#This Row],[Quantity]]*Z35-Table14[[#This Row],[STOCK]] -> 0 | N35: =IF(Table14[[#This Row],[Interim Value]]<0,0,Table14[[#This Row],[Interim Value]]) -> 0 | O35: =Table14[[#This Row],[Kitting Quantity]]*Table14[[#This Row],[TOTAL]] -> 0 | Q35: IMMEDIATE | Z35: =N1 -> 0
A36: 31 | B36: IC15001 | C36: 1 | D36: U1 | E36: SM3300 | F36: SO8 | H36: SEMTRONICS | I36: SEMTRONICS | J36: 15 | K36: =Table14[[#This Row],[Unit Cost]]*Table14[[#This Row],[Quantity]] -> 15 | L36: 0 | M36: =Table14[[#This Row],[Quantity]]*Z36-Table14[[#This Row],[STOCK]] -> 0 | N36: =IF(Table14[[#This Row],[Interim Value]]<0,0,Table14[[#This Row],[Interim Value]]) -> 0 | O36: =Table14[[#This Row],[Kitting Quantity]]*Table14[[#This Row],[TOTAL]] -> 0 | P36: SEM | Q36: IMMEDIATE | Z36: =N1 -> 0
A37: 32 | B37: PCB09073 | C37: 1 | D37: VER TL 5.13 | E37: PCB | F37: (18mm*299mm) | H37: UNIVERSAL CIRCUTS | I37: UNIVERSAL CIRCUTS | J37: 24 | K37: =Table14[[#This Row],[Unit Cost]]*Table14[[#This Row],[Quantity]] -> 24 | L37: 0 | M37: =Table14[[#This Row],[Quantity]]*Z37-Table14[[#This Row],[STOCK]] -> 0 | N37: =IF(Table14[[#This Row],[Interim Value]]<0,0,Table14[[#This Row],[Interim Value]]) -> 0 | O37: =Table14[[#This Row],[Kitting Quantity]]*Table14[[#This Row],[TOTAL]] -> 0 | P37: UNIVERSAL CIRCUTS | Q37: 60DAYS | Z37: =N1 -> 0
A38: 33 | C38: 1 | F38: EMS COST | H38: FLIP CHIP | J38: 13 | K38: =Table14[[#This Row],[Unit Cost]]*Table14[[#This Row],[Quantity]] -> 13 | L38: 0 | M38: =Table14[[#This Row],[Quantity]]*Z38-Table14[[#This Row],[STOCK]] -> 0 | N38: =IF(Table14[[#This Row],[Interim Value]]<0,0,Table14[[#This Row],[Interim Value]]) -> 0 | O38: =Table14[[#This Row],[Kitting Quantity]]*Table14[[#This Row],[TOTAL]] -> 0 | P38: FLIP CHIP | Q38: 60DAYS | Z38: =N1 -> 0
